[2024-11-27T01:52:59.849+0000] {local_task_job_runner.py:120} INFO - ::group::Pre task execution logs
[2024-11-27T01:52:59.856+0000] {taskinstance.py:2076} INFO - Dependencies all met for dep_context=non-requeueable deps ti=<TaskInstance: Citibike_Hist_Data_ETL.load_citibike_data manual__2024-11-27T01:47:16.122432+00:00 [queued]>
[2024-11-27T01:52:59.860+0000] {taskinstance.py:2076} INFO - Dependencies all met for dep_context=requeueable deps ti=<TaskInstance: Citibike_Hist_Data_ETL.load_citibike_data manual__2024-11-27T01:47:16.122432+00:00 [queued]>
[2024-11-27T01:52:59.860+0000] {taskinstance.py:2306} INFO - Starting attempt 2 of 2
[2024-11-27T01:52:59.865+0000] {taskinstance.py:2330} INFO - Executing <Task(_PythonDecoratedOperator): load_citibike_data> on 2024-11-27 01:47:16.122432+00:00
[2024-11-27T01:52:59.870+0000] {logging_mixin.py:188} WARNING - /home/***/.local/lib/python3.12/site-packages/***/task/task_runner/standard_task_runner.py:61 DeprecationWarning: This process (pid=29592) is multi-threaded, use of fork() may lead to deadlocks in the child.
[2024-11-27T01:52:59.871+0000] {standard_task_runner.py:63} INFO - Started process 29595 to run task
[2024-11-27T01:52:59.870+0000] {standard_task_runner.py:90} INFO - Running: ['***', 'tasks', 'run', 'Citibike_Hist_Data_ETL', 'load_citibike_data', 'manual__2024-11-27T01:47:16.122432+00:00', '--job-id', '296', '--raw', '--subdir', 'DAGS_FOLDER/ETL_citibike.py', '--cfg-path', '/tmp/tmpwcfbjnvc']
[2024-11-27T01:52:59.872+0000] {standard_task_runner.py:91} INFO - Job 296: Subtask load_citibike_data
[2024-11-27T01:52:59.895+0000] {task_command.py:426} INFO - Running <TaskInstance: Citibike_Hist_Data_ETL.load_citibike_data manual__2024-11-27T01:47:16.122432+00:00 [running]> on host 5de3b6ca18a7
[2024-11-27T01:52:59.933+0000] {taskinstance.py:2648} INFO - Exporting env vars: AIRFLOW_CTX_DAG_EMAIL='shatayu.thakur@sjsu.edu' AIRFLOW_CTX_DAG_OWNER='Shatayu' AIRFLOW_CTX_DAG_ID='Citibike_Hist_Data_ETL' AIRFLOW_CTX_TASK_ID='load_citibike_data' AIRFLOW_CTX_EXECUTION_DATE='2024-11-27T01:47:16.122432+00:00' AIRFLOW_CTX_TRY_NUMBER='2' AIRFLOW_CTX_DAG_RUN_ID='manual__2024-11-27T01:47:16.122432+00:00'
[2024-11-27T01:52:59.934+0000] {taskinstance.py:430} INFO - ::endgroup::
[2024-11-27T01:52:59.939+0000] {base.py:84} INFO - Using connection ID 'snowflake_conn' for task execution.
[2024-11-27T01:52:59.939+0000] {connection.py:399} INFO - Snowflake Connector for Python Version: 3.10.0, Python Version: 3.12.3, Platform: Linux-6.10.11-linuxkit-aarch64-with-glibc2.36
[2024-11-27T01:52:59.940+0000] {connection.py:1239} INFO - This connection is in OCSP Fail Open Mode. TLS Certificates would be checked for validity and revocation status. Any other Certificate Revocation related exceptions or OCSP Responder failures would be disregarded in favor of connectivity.
[2024-11-27T01:53:01.116+0000] {cursor.py:1149} INFO - Number of results in first chunk: 1
[2024-11-27T01:53:07.329+0000] {logging_mixin.py:188} INFO - Row count for data to be pushed:  2982715
[2024-11-27T01:53:07.577+0000] {cursor.py:1149} INFO - Number of results in first chunk: 1
[2024-11-27T01:53:07.761+0000] {cursor.py:1149} INFO - Number of results in first chunk: 1
[2024-11-27T01:53:07.947+0000] {cursor.py:1149} INFO - Number of results in first chunk: 1
[2024-11-27T01:53:07.949+0000] {logging_mixin.py:188} INFO - File format created successfully.
[2024-11-27T01:53:08.222+0000] {cursor.py:1149} INFO - Number of results in first chunk: 1
[2024-11-27T01:53:08.224+0000] {logging_mixin.py:188} INFO - Stage created successfully.
[2024-11-27T01:53:25.887+0000] {connectionpool.py:824} WARNING - Retrying (Retry(total=0, connect=None, read=None, redirect=None, status=None)) after connection broken by 'ProtocolError('Connection aborted.', OSError("(32, 'EPIPE')"))': /7ens0000-s/stages/35473dcf-ca11-4630-bed4-67d92b6bde68/cleaned_data.csv.gz
[2024-11-27T01:56:18.703+0000] {logging_mixin.py:188} INFO - File uploaded to stage: /opt/***/temp_store_proj/cleaned_data.csv
[2024-11-27T01:56:19.714+0000] {cursor.py:1149} INFO - Number of results in first chunk: 1
[2024-11-27T01:56:19.715+0000] {logging_mixin.py:188} INFO - Target Table Initialized and Ready to Store Historical Citibike Data from ETL
[2024-11-27T01:59:04.997+0000] {connectionpool.py:824} WARNING - Retrying (Retry(total=0, connect=None, read=None, redirect=None, status=None)) after connection broken by 'NewConnectionError('<snowflake.connector.vendored.urllib3.connection.HTTPSConnection object at 0xffff64b0fb00>: Failed to establish a new connection: [Errno -2] Name or service not known')': /queries/v1/query-request?requestId=461a407b-1283-46a1-b137-2cc1494cdd93&clientStartTime=1732672579716&retryCount=2&retryReason=None&request_guid=b2e10623-1c77-4ee6-9783-7ce9ecfcfebe
[2024-11-27T01:59:05.011+0000] {connectionpool.py:824} WARNING - Retrying (Retry(total=0, connect=None, read=None, redirect=None, status=None)) after connection broken by 'NewConnectionError('<snowflake.connector.vendored.urllib3.connection.HTTPSConnection object at 0xffff64b0e120>: Failed to establish a new connection: [Errno -2] Name or service not known')': /queries/v1/query-request?requestId=461a407b-1283-46a1-b137-2cc1494cdd93&clientStartTime=1732672579716&retryCount=3&retryReason=None&request_guid=6900bbb4-cb4b-4a05-a30a-ef62e3f5453f
[2024-11-27T01:59:06.048+0000] {connectionpool.py:824} WARNING - Retrying (Retry(total=0, connect=None, read=None, redirect=None, status=None)) after connection broken by 'NewConnectionError('<snowflake.connector.vendored.urllib3.connection.HTTPSConnection object at 0xffff64b0e090>: Failed to establish a new connection: [Errno -2] Name or service not known')': /queries/v1/query-request?requestId=461a407b-1283-46a1-b137-2cc1494cdd93&clientStartTime=1732672579716&retryCount=4&retryReason=None&request_guid=eec52632-a161-4a54-8ddd-edb2b7314c3a
[2024-11-27T01:59:14.071+0000] {connectionpool.py:824} WARNING - Retrying (Retry(total=0, connect=None, read=None, redirect=None, status=None)) after connection broken by 'NewConnectionError('<snowflake.connector.vendored.urllib3.connection.HTTPSConnection object at 0xffff64b0c1a0>: Failed to establish a new connection: [Errno -2] Name or service not known')': /queries/v1/query-request?requestId=461a407b-1283-46a1-b137-2cc1494cdd93&clientStartTime=1732672579716&retryCount=5&retryReason=None&request_guid=e4fae85b-ccba-4d8a-a757-78adb45631fc
[2024-11-27T01:59:30.091+0000] {connectionpool.py:824} WARNING - Retrying (Retry(total=0, connect=None, read=None, redirect=None, status=None)) after connection broken by 'NewConnectionError('<snowflake.connector.vendored.urllib3.connection.HTTPSConnection object at 0xffff64b0d5e0>: Failed to establish a new connection: [Errno -2] Name or service not known')': /queries/v1/query-request?requestId=461a407b-1283-46a1-b137-2cc1494cdd93&clientStartTime=1732672579716&retryCount=6&retryReason=None&request_guid=135bda79-d043-441e-bdb3-1d820beab461
[2024-11-27T01:59:40.115+0000] {connectionpool.py:824} WARNING - Retrying (Retry(total=0, connect=None, read=None, redirect=None, status=None)) after connection broken by 'NewConnectionError('<snowflake.connector.vendored.urllib3.connection.HTTPSConnection object at 0xffff64b0c680>: Failed to establish a new connection: [Errno -2] Name or service not known')': /queries/v1/query-request?requestId=461a407b-1283-46a1-b137-2cc1494cdd93&clientStartTime=1732672579716&retryCount=7&retryReason=None&request_guid=98557cf6-859c-4020-b0a3-337a1929b080
[2024-11-27T01:59:54.138+0000] {connectionpool.py:824} WARNING - Retrying (Retry(total=0, connect=None, read=None, redirect=None, status=None)) after connection broken by 'NewConnectionError('<snowflake.connector.vendored.urllib3.connection.HTTPSConnection object at 0xffff64b0f4d0>: Failed to establish a new connection: [Errno -2] Name or service not known')': /queries/v1/query-request?requestId=461a407b-1283-46a1-b137-2cc1494cdd93&clientStartTime=1732672579716&retryCount=8&retryReason=None&request_guid=e392378f-aa6a-4145-b92b-29a238c58679
[2024-11-27T02:00:05.161+0000] {connectionpool.py:824} WARNING - Retrying (Retry(total=0, connect=None, read=None, redirect=None, status=None)) after connection broken by 'NewConnectionError('<snowflake.connector.vendored.urllib3.connection.HTTPSConnection object at 0xffff64b0f230>: Failed to establish a new connection: [Errno -2] Name or service not known')': /queries/v1/query-request?requestId=461a407b-1283-46a1-b137-2cc1494cdd93&clientStartTime=1732672579716&retryCount=9&retryReason=None&request_guid=1912bd84-12ea-4850-aaf1-757fa0966260
[2024-11-27T02:00:19.187+0000] {connectionpool.py:824} WARNING - Retrying (Retry(total=0, connect=None, read=None, redirect=None, status=None)) after connection broken by 'NewConnectionError('<snowflake.connector.vendored.urllib3.connection.HTTPSConnection object at 0xffff64b0e180>: Failed to establish a new connection: [Errno -2] Name or service not known')': /queries/v1/query-request?requestId=461a407b-1283-46a1-b137-2cc1494cdd93&clientStartTime=1732672579716&retryCount=10&retryReason=None&request_guid=23d42f42-1025-4d84-8706-5d02b7d5e66f
[2024-11-27T02:00:33.214+0000] {connectionpool.py:824} WARNING - Retrying (Retry(total=0, connect=None, read=None, redirect=None, status=None)) after connection broken by 'NewConnectionError('<snowflake.connector.vendored.urllib3.connection.HTTPSConnection object at 0xffff58d7b620>: Failed to establish a new connection: [Errno -2] Name or service not known')': /queries/v1/query-request?requestId=461a407b-1283-46a1-b137-2cc1494cdd93&clientStartTime=1732672579716&retryCount=11&retryReason=None&request_guid=44bff66e-7098-4b28-9430-5d88c82d9dd2
[2024-11-27T02:00:36.233+0000] {connectionpool.py:824} WARNING - Retrying (Retry(total=0, connect=None, read=None, redirect=None, status=None)) after connection broken by 'NewConnectionError('<snowflake.connector.vendored.urllib3.connection.HTTPSConnection object at 0xffff64b0bd70>: Failed to establish a new connection: [Errno -2] Name or service not known')': /queries/v1/query-request?requestId=461a407b-1283-46a1-b137-2cc1494cdd93&clientStartTime=1732672579716&retryCount=12&retryReason=None&request_guid=9cc873a3-7d34-4c77-b774-99a6e11bfe21
[2024-11-27T02:00:40.255+0000] {connectionpool.py:824} WARNING - Retrying (Retry(total=0, connect=None, read=None, redirect=None, status=None)) after connection broken by 'NewConnectionError('<snowflake.connector.vendored.urllib3.connection.HTTPSConnection object at 0xffff64b0c980>: Failed to establish a new connection: [Errno -2] Name or service not known')': /queries/v1/query-request?requestId=461a407b-1283-46a1-b137-2cc1494cdd93&clientStartTime=1732672579716&retryCount=13&retryReason=None&request_guid=0b282f2c-cb38-477d-833f-3220aeba5b51
[2024-11-27T02:00:49.280+0000] {connectionpool.py:824} WARNING - Retrying (Retry(total=0, connect=None, read=None, redirect=None, status=None)) after connection broken by 'NewConnectionError('<snowflake.connector.vendored.urllib3.connection.HTTPSConnection object at 0xffff64b0eba0>: Failed to establish a new connection: [Errno -2] Name or service not known')': /queries/v1/query-request?requestId=461a407b-1283-46a1-b137-2cc1494cdd93&clientStartTime=1732672579716&retryCount=14&retryReason=None&request_guid=a9384376-988e-4694-aae2-f5a16d76e821
[2024-11-27T02:00:56.298+0000] {connectionpool.py:824} WARNING - Retrying (Retry(total=0, connect=None, read=None, redirect=None, status=None)) after connection broken by 'NewConnectionError('<snowflake.connector.vendored.urllib3.connection.HTTPSConnection object at 0xffff64b0a060>: Failed to establish a new connection: [Errno -2] Name or service not known')': /queries/v1/query-request?requestId=461a407b-1283-46a1-b137-2cc1494cdd93&clientStartTime=1732672579716&retryCount=15&retryReason=None&request_guid=b9b6ab27-18f3-4497-88b0-c05524e59540
[2024-11-27T02:01:02.326+0000] {connectionpool.py:824} WARNING - Retrying (Retry(total=0, connect=None, read=None, redirect=None, status=None)) after connection broken by 'NewConnectionError('<snowflake.connector.vendored.urllib3.connection.HTTPSConnection object at 0xffff64b0b5c0>: Failed to establish a new connection: [Errno -2] Name or service not known')': /queries/v1/query-request?requestId=461a407b-1283-46a1-b137-2cc1494cdd93&clientStartTime=1732672579716&retryCount=16&retryReason=None&request_guid=e3bbd504-2dd3-4d06-b15c-2e2667844e35
[2024-11-27T02:01:10.345+0000] {connectionpool.py:824} WARNING - Retrying (Retry(total=0, connect=None, read=None, redirect=None, status=None)) after connection broken by 'NewConnectionError('<snowflake.connector.vendored.urllib3.connection.HTTPSConnection object at 0xffff64b0b3e0>: Failed to establish a new connection: [Errno -2] Name or service not known')': /queries/v1/query-request?requestId=461a407b-1283-46a1-b137-2cc1494cdd93&clientStartTime=1732672579716&retryCount=17&retryReason=None&request_guid=aee89269-21f0-4d6e-8ff7-88c54a1464b2
[2024-11-27T02:01:15.366+0000] {connectionpool.py:824} WARNING - Retrying (Retry(total=0, connect=None, read=None, redirect=None, status=None)) after connection broken by 'NewConnectionError('<snowflake.connector.vendored.urllib3.connection.HTTPSConnection object at 0xffff64b0a330>: Failed to establish a new connection: [Errno -2] Name or service not known')': /queries/v1/query-request?requestId=461a407b-1283-46a1-b137-2cc1494cdd93&clientStartTime=1732672579716&retryCount=18&retryReason=None&request_guid=8bb59bd6-459f-4017-93bc-0eafdb09ab11
[2024-11-27T02:01:19.388+0000] {connectionpool.py:824} WARNING - Retrying (Retry(total=0, connect=None, read=None, redirect=None, status=None)) after connection broken by 'NewConnectionError('<snowflake.connector.vendored.urllib3.connection.HTTPSConnection object at 0xffff64b0caa0>: Failed to establish a new connection: [Errno -2] Name or service not known')': /queries/v1/query-request?requestId=461a407b-1283-46a1-b137-2cc1494cdd93&clientStartTime=1732672579716&retryCount=19&retryReason=None&request_guid=ca6400cc-7140-41bb-8c90-e1e257d16f61
[2024-11-27T02:01:32.410+0000] {connectionpool.py:824} WARNING - Retrying (Retry(total=0, connect=None, read=None, redirect=None, status=None)) after connection broken by 'NewConnectionError('<snowflake.connector.vendored.urllib3.connection.HTTPSConnection object at 0xffff64b0fb30>: Failed to establish a new connection: [Errno -2] Name or service not known')': /queries/v1/query-request?requestId=461a407b-1283-46a1-b137-2cc1494cdd93&clientStartTime=1732672579716&retryCount=20&retryReason=None&request_guid=9d457b02-618f-4073-91d5-b88c4974ea91
[2024-11-27T02:01:40.422+0000] {connectionpool.py:824} WARNING - Retrying (Retry(total=0, connect=None, read=None, redirect=None, status=None)) after connection broken by 'NewConnectionError('<snowflake.connector.vendored.urllib3.connection.HTTPSConnection object at 0xffff64b086e0>: Failed to establish a new connection: [Errno -2] Name or service not known')': /queries/v1/query-request?requestId=461a407b-1283-46a1-b137-2cc1494cdd93&clientStartTime=1732672579716&retryCount=21&retryReason=None&request_guid=d2873e9f-866a-4756-9c12-592bac37d573
[2024-11-27T02:01:48.442+0000] {connectionpool.py:824} WARNING - Retrying (Retry(total=0, connect=None, read=None, redirect=None, status=None)) after connection broken by 'NewConnectionError('<snowflake.connector.vendored.urllib3.connection.HTTPSConnection object at 0xffff64b081d0>: Failed to establish a new connection: [Errno -2] Name or service not known')': /queries/v1/query-request?requestId=461a407b-1283-46a1-b137-2cc1494cdd93&clientStartTime=1732672579716&retryCount=22&retryReason=None&request_guid=03a9183d-b6ee-4fff-a8ca-f638a8ed440f
[2024-11-27T02:02:01.460+0000] {connectionpool.py:824} WARNING - Retrying (Retry(total=0, connect=None, read=None, redirect=None, status=None)) after connection broken by 'NewConnectionError('<snowflake.connector.vendored.urllib3.connection.HTTPSConnection object at 0xffff64b0b140>: Failed to establish a new connection: [Errno -2] Name or service not known')': /queries/v1/query-request?requestId=461a407b-1283-46a1-b137-2cc1494cdd93&clientStartTime=1732672579716&retryCount=23&retryReason=None&request_guid=6517904e-0aee-4427-a86d-95dc6158d027
[2024-11-27T02:02:03.479+0000] {connectionpool.py:824} WARNING - Retrying (Retry(total=0, connect=None, read=None, redirect=None, status=None)) after connection broken by 'NewConnectionError('<snowflake.connector.vendored.urllib3.connection.HTTPSConnection object at 0xffff64b0bf20>: Failed to establish a new connection: [Errno -2] Name or service not known')': /queries/v1/query-request?requestId=461a407b-1283-46a1-b137-2cc1494cdd93&clientStartTime=1732672579716&retryCount=24&retryReason=None&request_guid=6d3b774b-53c5-480c-bcf8-05aa3219feb9
[2024-11-27T02:02:13.502+0000] {connectionpool.py:824} WARNING - Retrying (Retry(total=0, connect=None, read=None, redirect=None, status=None)) after connection broken by 'NewConnectionError('<snowflake.connector.vendored.urllib3.connection.HTTPSConnection object at 0xffff64b0acf0>: Failed to establish a new connection: [Errno -2] Name or service not known')': /queries/v1/query-request?requestId=461a407b-1283-46a1-b137-2cc1494cdd93&clientStartTime=1732672579716&retryCount=25&retryReason=None&request_guid=c5134405-d132-4fda-8676-ab9062e19ef4
[2024-11-27T02:02:19.398+0000] {cursor.py:1149} INFO - Number of results in first chunk: 1
[2024-11-27T02:02:19.400+0000] {logging_mixin.py:188} INFO - Data loaded successfully into Snowflake table.
[2024-11-27T02:02:19.668+0000] {cursor.py:1149} INFO - Number of results in first chunk: 1
[2024-11-27T02:02:19.670+0000] {logging_mixin.py:188} INFO - Transaction committed. Data load complete.
[2024-11-27T02:02:19.671+0000] {connection.py:762} INFO - closed
[2024-11-27T02:02:19.787+0000] {connection.py:768} INFO - No async queries seem to be running, deleting session
[2024-11-27T02:02:19.917+0000] {python.py:237} INFO - Done. Returned value was: None
[2024-11-27T02:02:19.920+0000] {taskinstance.py:441} INFO - ::group::Post task execution logs
[2024-11-27T02:02:19.948+0000] {taskinstance.py:1206} INFO - Marking task as SUCCESS. dag_id=Citibike_Hist_Data_ETL, task_id=load_citibike_data, run_id=manual__2024-11-27T01:47:16.122432+00:00, execution_date=20241127T014716, start_date=20241127T015259, end_date=20241127T020219
[2024-11-27T02:02:20.043+0000] {local_task_job_runner.py:240} INFO - Task exited with return code 0
[2024-11-27T02:02:20.069+0000] {taskinstance.py:3498} INFO - 1 downstream tasks scheduled from follow-on schedule check
[2024-11-27T02:02:20.069+0000] {local_task_job_runner.py:222} INFO - ::endgroup::
