[2024-11-26T10:47:25.398+0000] {local_task_job_runner.py:120} INFO - ::group::Pre task execution logs
[2024-11-26T10:47:25.406+0000] {taskinstance.py:2076} INFO - Dependencies all met for dep_context=non-requeueable deps ti=<TaskInstance: Weather_Realtime_Data_ETL.transform_weather_current_data manual__2024-11-26T10:41:21.790736+00:00 [queued]>
[2024-11-26T10:47:25.409+0000] {taskinstance.py:2076} INFO - Dependencies all met for dep_context=requeueable deps ti=<TaskInstance: Weather_Realtime_Data_ETL.transform_weather_current_data manual__2024-11-26T10:41:21.790736+00:00 [queued]>
[2024-11-26T10:47:25.410+0000] {taskinstance.py:2306} INFO - Starting attempt 1 of 2
[2024-11-26T10:47:25.415+0000] {taskinstance.py:2330} INFO - Executing <Task(_PythonDecoratedOperator): transform_weather_current_data> on 2024-11-26 10:41:21.790736+00:00
[2024-11-26T10:47:25.419+0000] {logging_mixin.py:188} WARNING - /home/***/.local/lib/python3.12/site-packages/***/task/task_runner/standard_task_runner.py:61 DeprecationWarning: This process (pid=6747) is multi-threaded, use of fork() may lead to deadlocks in the child.
[2024-11-26T10:47:25.420+0000] {standard_task_runner.py:63} INFO - Started process 6750 to run task
[2024-11-26T10:47:25.420+0000] {standard_task_runner.py:90} INFO - Running: ['***', 'tasks', 'run', 'Weather_Realtime_Data_ETL', 'transform_weather_current_data', 'manual__2024-11-26T10:41:21.790736+00:00', '--job-id', '205', '--raw', '--subdir', 'DAGS_FOLDER/ETL_weather_realtime.py', '--cfg-path', '/tmp/tmpyt9x3kov']
[2024-11-26T10:47:25.421+0000] {standard_task_runner.py:91} INFO - Job 205: Subtask transform_weather_current_data
[2024-11-26T10:47:25.442+0000] {task_command.py:426} INFO - Running <TaskInstance: Weather_Realtime_Data_ETL.transform_weather_current_data manual__2024-11-26T10:41:21.790736+00:00 [running]> on host 5de3b6ca18a7
[2024-11-26T10:47:25.503+0000] {taskinstance.py:2648} INFO - Exporting env vars: AIRFLOW_CTX_DAG_EMAIL='shatayu.thakur@sjsu.edu' AIRFLOW_CTX_DAG_OWNER='Shatayu' AIRFLOW_CTX_DAG_ID='Weather_Realtime_Data_ETL' AIRFLOW_CTX_TASK_ID='transform_weather_current_data' AIRFLOW_CTX_EXECUTION_DATE='2024-11-26T10:41:21.790736+00:00' AIRFLOW_CTX_TRY_NUMBER='1' AIRFLOW_CTX_DAG_RUN_ID='manual__2024-11-26T10:41:21.790736+00:00'
[2024-11-26T10:47:25.505+0000] {taskinstance.py:430} INFO - ::endgroup::
[2024-11-26T10:47:25.507+0000] {logging_mixin.py:188} INFO - Transformed Data for Jersey City, New Jersey:
[2024-11-26T10:47:25.512+0000] {logging_mixin.py:188} INFO -                   date  ...                                        hour
0 2024-11-26 05:45:00  ...  0    5
Name: last_updated_dt, dtype: int32

[1 rows x 9 columns]
[2024-11-26T10:47:25.512+0000] {logging_mixin.py:188} INFO - Transformed Data Features:  Index(['date', 'temp', 'temp_feel', 'humidity', 'rain', 'year', 'month', 'day',
       'hour'],
      dtype='object')
[2024-11-26T10:47:25.513+0000] {python.py:237} INFO - Done. Returned value was:                  date  ...                                        hour
0 2024-11-26 05:45:00  ...  0    5
Name: last_updated_dt, dtype: int32

[1 rows x 9 columns]
[2024-11-26T10:47:25.516+0000] {taskinstance.py:441} INFO - ::group::Post task execution logs
[2024-11-26T10:47:25.520+0000] {xcom.py:675} ERROR - ('Could not convert 0    53.1\nName: temp_f, dtype: float64 with type Series: did not recognize Python value type when inferring an Arrow data type', 'Conversion failed for column temp with type object'). If you are using pickle instead of JSON for XCom, then you need to enable pickle support for XCom in your *** config or make sure to decorate your object with attr.
[2024-11-26T10:47:25.521+0000] {taskinstance.py:2905} ERROR - Task failed with exception
Traceback (most recent call last):
  File "/home/airflow/.local/lib/python3.12/site-packages/airflow/models/taskinstance.py", line 486, in _execute_task
    task_instance.xcom_push(key=XCOM_RETURN_KEY, value=xcom_value, session=session)
  File "/home/airflow/.local/lib/python3.12/site-packages/airflow/utils/session.py", line 76, in wrapper
    return func(*args, **kwargs)
           ^^^^^^^^^^^^^^^^^^^^^
  File "/home/airflow/.local/lib/python3.12/site-packages/airflow/models/taskinstance.py", line 3197, in xcom_push
    XCom.set(
  File "/home/airflow/.local/lib/python3.12/site-packages/airflow/utils/session.py", line 76, in wrapper
    return func(*args, **kwargs)
           ^^^^^^^^^^^^^^^^^^^^^
  File "/home/airflow/.local/lib/python3.12/site-packages/airflow/models/xcom.py", line 246, in set
    value = cls.serialize_value(
            ^^^^^^^^^^^^^^^^^^^^
  File "/home/airflow/.local/lib/python3.12/site-packages/airflow/models/xcom.py", line 673, in serialize_value
    return json.dumps(value, cls=XComEncoder).encode("UTF-8")
           ^^^^^^^^^^^^^^^^^^^^^^^^^^^^^^^^^^
  File "/usr/local/lib/python3.12/json/__init__.py", line 238, in dumps
    **kw).encode(obj)
          ^^^^^^^^^^^
  File "/home/airflow/.local/lib/python3.12/site-packages/airflow/utils/json.py", line 104, in encode
    return super().encode(o)
           ^^^^^^^^^^^^^^^^^
  File "/usr/local/lib/python3.12/json/encoder.py", line 200, in encode
    chunks = self.iterencode(o, _one_shot=True)
             ^^^^^^^^^^^^^^^^^^^^^^^^^^^^^^^^^^
  File "/usr/local/lib/python3.12/json/encoder.py", line 258, in iterencode
    return _iterencode(o, 0)
           ^^^^^^^^^^^^^^^^^
  File "/home/airflow/.local/lib/python3.12/site-packages/airflow/utils/json.py", line 91, in default
    return serialize(o)
           ^^^^^^^^^^^^
  File "/home/airflow/.local/lib/python3.12/site-packages/airflow/serialization/serde.py", line 148, in serialize
    data, serialized_classname, version, is_serialized = _serializers[qn].serialize(o)
                                                         ^^^^^^^^^^^^^^^^^^^^^^^^^^^^^
  File "/home/airflow/.local/lib/python3.12/site-packages/airflow/serialization/serializers/pandas.py", line 49, in serialize
    table = pa.Table.from_pandas(o)
            ^^^^^^^^^^^^^^^^^^^^^^^
  File "pyarrow/table.pxi", line 4525, in pyarrow.lib.Table.from_pandas
  File "/home/airflow/.local/lib/python3.12/site-packages/pyarrow/pandas_compat.py", line 611, in dataframe_to_arrays
    arrays = [convert_column(c, f)
              ^^^^^^^^^^^^^^^^^^^^
  File "/home/airflow/.local/lib/python3.12/site-packages/pyarrow/pandas_compat.py", line 598, in convert_column
    raise e
  File "/home/airflow/.local/lib/python3.12/site-packages/pyarrow/pandas_compat.py", line 592, in convert_column
    result = pa.array(col, type=type_, from_pandas=True, safe=safe)
             ^^^^^^^^^^^^^^^^^^^^^^^^^^^^^^^^^^^^^^^^^^^^^^^^^^^^^^
  File "pyarrow/array.pxi", line 345, in pyarrow.lib.array
  File "pyarrow/array.pxi", line 85, in pyarrow.lib._ndarray_to_array
  File "pyarrow/error.pxi", line 91, in pyarrow.lib.check_status
pyarrow.lib.ArrowInvalid: ('Could not convert 0    53.1\nName: temp_f, dtype: float64 with type Series: did not recognize Python value type when inferring an Arrow data type', 'Conversion failed for column temp with type object')
[2024-11-26T10:47:25.525+0000] {taskinstance.py:1206} INFO - Marking task as UP_FOR_RETRY. dag_id=Weather_Realtime_Data_ETL, task_id=transform_weather_current_data, run_id=manual__2024-11-26T10:41:21.790736+00:00, execution_date=20241126T104121, start_date=20241126T104725, end_date=20241126T104725
[2024-11-26T10:47:25.531+0000] {logging_mixin.py:188} WARNING - /home/***/.local/lib/python3.12/site-packages/***/utils/email.py:154 RemovedInAirflow3Warning: Fetching SMTP credentials from configuration variables will be deprecated in a future release. Please set credentials using a connection instead.
[2024-11-26T10:47:25.531+0000] {configuration.py:1050} WARNING - section/key [smtp/smtp_user] not found in config
[2024-11-26T10:47:25.532+0000] {email.py:271} INFO - Email alerting: attempt 1
[2024-11-26T10:47:25.535+0000] {configuration.py:1050} WARNING - section/key [smtp/smtp_user] not found in config
[2024-11-26T10:47:25.535+0000] {email.py:271} INFO - Email alerting: attempt 1
[2024-11-26T10:47:25.535+0000] {taskinstance.py:879} ERROR - Failed to send email to: ['shatayu.thakur@sjsu.edu']
Traceback (most recent call last):
  File "/home/airflow/.local/lib/python3.12/site-packages/airflow/models/taskinstance.py", line 2479, in _run_raw_task
    self._execute_task_with_callbacks(context, test_mode, session=session)
  File "/home/airflow/.local/lib/python3.12/site-packages/airflow/models/taskinstance.py", line 2676, in _execute_task_with_callbacks
    result = self._execute_task(context, task_orig)
             ^^^^^^^^^^^^^^^^^^^^^^^^^^^^^^^^^^^^^^
  File "/home/airflow/.local/lib/python3.12/site-packages/airflow/models/taskinstance.py", line 2701, in _execute_task
    return _execute_task(self, context, task_orig)
           ^^^^^^^^^^^^^^^^^^^^^^^^^^^^^^^^^^^^^^^
  File "/home/airflow/.local/lib/python3.12/site-packages/airflow/models/taskinstance.py", line 486, in _execute_task
    task_instance.xcom_push(key=XCOM_RETURN_KEY, value=xcom_value, session=session)
  File "/home/airflow/.local/lib/python3.12/site-packages/airflow/utils/session.py", line 76, in wrapper
    return func(*args, **kwargs)
           ^^^^^^^^^^^^^^^^^^^^^
  File "/home/airflow/.local/lib/python3.12/site-packages/airflow/models/taskinstance.py", line 3197, in xcom_push
    XCom.set(
  File "/home/airflow/.local/lib/python3.12/site-packages/airflow/utils/session.py", line 76, in wrapper
    return func(*args, **kwargs)
           ^^^^^^^^^^^^^^^^^^^^^
  File "/home/airflow/.local/lib/python3.12/site-packages/airflow/models/xcom.py", line 246, in set
    value = cls.serialize_value(
            ^^^^^^^^^^^^^^^^^^^^
  File "/home/airflow/.local/lib/python3.12/site-packages/airflow/models/xcom.py", line 673, in serialize_value
    return json.dumps(value, cls=XComEncoder).encode("UTF-8")
           ^^^^^^^^^^^^^^^^^^^^^^^^^^^^^^^^^^
  File "/usr/local/lib/python3.12/json/__init__.py", line 238, in dumps
    **kw).encode(obj)
          ^^^^^^^^^^^
  File "/home/airflow/.local/lib/python3.12/site-packages/airflow/utils/json.py", line 104, in encode
    return super().encode(o)
           ^^^^^^^^^^^^^^^^^
  File "/usr/local/lib/python3.12/json/encoder.py", line 200, in encode
    chunks = self.iterencode(o, _one_shot=True)
             ^^^^^^^^^^^^^^^^^^^^^^^^^^^^^^^^^^
  File "/usr/local/lib/python3.12/json/encoder.py", line 258, in iterencode
    return _iterencode(o, 0)
           ^^^^^^^^^^^^^^^^^
  File "/home/airflow/.local/lib/python3.12/site-packages/airflow/utils/json.py", line 91, in default
    return serialize(o)
           ^^^^^^^^^^^^
  File "/home/airflow/.local/lib/python3.12/site-packages/airflow/serialization/serde.py", line 148, in serialize
    data, serialized_classname, version, is_serialized = _serializers[qn].serialize(o)
                                                         ^^^^^^^^^^^^^^^^^^^^^^^^^^^^^
  File "/home/airflow/.local/lib/python3.12/site-packages/airflow/serialization/serializers/pandas.py", line 49, in serialize
    table = pa.Table.from_pandas(o)
            ^^^^^^^^^^^^^^^^^^^^^^^
  File "pyarrow/table.pxi", line 4525, in pyarrow.lib.Table.from_pandas
  File "/home/airflow/.local/lib/python3.12/site-packages/pyarrow/pandas_compat.py", line 611, in dataframe_to_arrays
    arrays = [convert_column(c, f)
              ^^^^^^^^^^^^^^^^^^^^
  File "/home/airflow/.local/lib/python3.12/site-packages/pyarrow/pandas_compat.py", line 598, in convert_column
    raise e
  File "/home/airflow/.local/lib/python3.12/site-packages/pyarrow/pandas_compat.py", line 592, in convert_column
    result = pa.array(col, type=type_, from_pandas=True, safe=safe)
             ^^^^^^^^^^^^^^^^^^^^^^^^^^^^^^^^^^^^^^^^^^^^^^^^^^^^^^
  File "pyarrow/array.pxi", line 345, in pyarrow.lib.array
  File "pyarrow/array.pxi", line 85, in pyarrow.lib._ndarray_to_array
  File "pyarrow/error.pxi", line 91, in pyarrow.lib.check_status
pyarrow.lib.ArrowInvalid: ('Could not convert 0    53.1\nName: temp_f, dtype: float64 with type Series: did not recognize Python value type when inferring an Arrow data type', 'Conversion failed for column temp with type object')

During handling of the above exception, another exception occurred:

Traceback (most recent call last):
  File "/home/airflow/.local/lib/python3.12/site-packages/airflow/models/taskinstance.py", line 1063, in _email_alert
    send_email(task.email, subject, html_content)
  File "/home/airflow/.local/lib/python3.12/site-packages/airflow/utils/email.py", line 80, in send_email
    return backend(
           ^^^^^^^^
  File "/home/airflow/.local/lib/python3.12/site-packages/airflow/utils/email.py", line 154, in send_email_smtp
    send_mime_email(e_from=mail_from, e_to=recipients, mime_msg=msg, conn_id=conn_id, dryrun=dryrun)
  File "/home/airflow/.local/lib/python3.12/site-packages/airflow/utils/email.py", line 273, in send_mime_email
    smtp_conn = _get_smtp_connection(smtp_host, smtp_port, smtp_timeout, smtp_ssl)
                ^^^^^^^^^^^^^^^^^^^^^^^^^^^^^^^^^^^^^^^^^^^^^^^^^^^^^^^^^^^^^^^^^^
  File "/home/airflow/.local/lib/python3.12/site-packages/airflow/utils/email.py", line 317, in _get_smtp_connection
    return smtplib.SMTP(host=host, port=port, timeout=timeout)
           ^^^^^^^^^^^^^^^^^^^^^^^^^^^^^^^^^^^^^^^^^^^^^^^^^^^
  File "/usr/local/lib/python3.12/smtplib.py", line 255, in __init__
    (code, msg) = self.connect(host, port)
                  ^^^^^^^^^^^^^^^^^^^^^^^^
  File "/usr/local/lib/python3.12/smtplib.py", line 341, in connect
    self.sock = self._get_socket(host, port, self.timeout)
                ^^^^^^^^^^^^^^^^^^^^^^^^^^^^^^^^^^^^^^^^^^
  File "/usr/local/lib/python3.12/smtplib.py", line 312, in _get_socket
    return socket.create_connection((host, port), timeout,
           ^^^^^^^^^^^^^^^^^^^^^^^^^^^^^^^^^^^^^^^^^^^^^^^
  File "/usr/local/lib/python3.12/socket.py", line 852, in create_connection
    raise exceptions[0]
  File "/usr/local/lib/python3.12/socket.py", line 837, in create_connection
    sock.connect(sa)
ConnectionRefusedError: [Errno 111] Connection refused

During handling of the above exception, another exception occurred:

Traceback (most recent call last):
  File "/home/airflow/.local/lib/python3.12/site-packages/airflow/models/taskinstance.py", line 877, in _handle_failure
    task_instance.email_alert(error, failure_context["task"])
  File "/home/airflow/.local/lib/python3.12/site-packages/airflow/models/taskinstance.py", line 3163, in email_alert
    _email_alert(task_instance=self, exception=exception, task=task)
  File "/home/airflow/.local/lib/python3.12/site-packages/airflow/models/taskinstance.py", line 1065, in _email_alert
    send_email(task.email, subject, html_content_err)
  File "/home/airflow/.local/lib/python3.12/site-packages/airflow/utils/email.py", line 80, in send_email
    return backend(
           ^^^^^^^^
  File "/home/airflow/.local/lib/python3.12/site-packages/airflow/utils/email.py", line 154, in send_email_smtp
    send_mime_email(e_from=mail_from, e_to=recipients, mime_msg=msg, conn_id=conn_id, dryrun=dryrun)
  File "/home/airflow/.local/lib/python3.12/site-packages/airflow/utils/email.py", line 273, in send_mime_email
    smtp_conn = _get_smtp_connection(smtp_host, smtp_port, smtp_timeout, smtp_ssl)
                ^^^^^^^^^^^^^^^^^^^^^^^^^^^^^^^^^^^^^^^^^^^^^^^^^^^^^^^^^^^^^^^^^^
  File "/home/airflow/.local/lib/python3.12/site-packages/airflow/utils/email.py", line 317, in _get_smtp_connection
    return smtplib.SMTP(host=host, port=port, timeout=timeout)
           ^^^^^^^^^^^^^^^^^^^^^^^^^^^^^^^^^^^^^^^^^^^^^^^^^^^
  File "/usr/local/lib/python3.12/smtplib.py", line 255, in __init__
    (code, msg) = self.connect(host, port)
                  ^^^^^^^^^^^^^^^^^^^^^^^^
  File "/usr/local/lib/python3.12/smtplib.py", line 341, in connect
    self.sock = self._get_socket(host, port, self.timeout)
                ^^^^^^^^^^^^^^^^^^^^^^^^^^^^^^^^^^^^^^^^^^
  File "/usr/local/lib/python3.12/smtplib.py", line 312, in _get_socket
    return socket.create_connection((host, port), timeout,
           ^^^^^^^^^^^^^^^^^^^^^^^^^^^^^^^^^^^^^^^^^^^^^^^
  File "/usr/local/lib/python3.12/socket.py", line 852, in create_connection
    raise exceptions[0]
  File "/usr/local/lib/python3.12/socket.py", line 837, in create_connection
    sock.connect(sa)
ConnectionRefusedError: [Errno 111] Connection refused
[2024-11-26T10:47:25.542+0000] {standard_task_runner.py:110} ERROR - Failed to execute job 205 for task transform_weather_current_data (('Could not convert 0    53.1\nName: temp_f, dtype: float64 with type Series: did not recognize Python value type when inferring an Arrow data type', 'Conversion failed for column temp with type object'); 6750)
[2024-11-26T10:47:25.562+0000] {local_task_job_runner.py:240} INFO - Task exited with return code 1
[2024-11-26T10:47:25.571+0000] {taskinstance.py:3498} INFO - 0 downstream tasks scheduled from follow-on schedule check
[2024-11-26T10:47:25.571+0000] {local_task_job_runner.py:222} INFO - ::endgroup::
