[2024-11-25T00:18:35.570+0000] {processor.py:161} INFO - Started process (PID=301) to work on /opt/airflow/dags/ETL_weather_hist.py
[2024-11-25T00:18:35.572+0000] {processor.py:830} INFO - Processing file /opt/airflow/dags/ETL_weather_hist.py for tasks to queue
[2024-11-25T00:18:35.578+0000] {logging_mixin.py:188} INFO - [2024-11-25T00:18:35.577+0000] {dagbag.py:545} INFO - Filling up the DagBag from /opt/airflow/dags/ETL_weather_hist.py
[2024-11-25T00:18:35.630+0000] {logging_mixin.py:188} INFO - [2024-11-25T00:18:35.626+0000] {dagbag.py:355} ERROR - Failed to import: /opt/airflow/dags/ETL_weather_hist.py
Traceback (most recent call last):
  File "/home/airflow/.local/lib/python3.12/site-packages/airflow/models/dagbag.py", line 351, in parse
    loader.exec_module(new_module)
  File "<frozen importlib._bootstrap_external>", line 995, in exec_module
  File "<frozen importlib._bootstrap>", line 488, in _call_with_frames_removed
  File "/opt/airflow/dags/ETL_weather_hist.py", line 102, in <module>
    extracted_df = extract_citibike_data(start_year, start_month, end_year, end_month)
                   ^^^^^^^^^^^^^^^^^^^^^
NameError: name 'extract_citibike_data' is not defined
[2024-11-25T00:18:35.635+0000] {processor.py:842} WARNING - No viable dags retrieved from /opt/airflow/dags/ETL_weather_hist.py
[2024-11-25T00:18:35.660+0000] {processor.py:183} INFO - Processing /opt/airflow/dags/ETL_weather_hist.py took 0.097 seconds
[2024-11-25T00:19:05.980+0000] {processor.py:161} INFO - Started process (PID=335) to work on /opt/airflow/dags/ETL_weather_hist.py
[2024-11-25T00:19:05.981+0000] {processor.py:830} INFO - Processing file /opt/airflow/dags/ETL_weather_hist.py for tasks to queue
[2024-11-25T00:19:05.984+0000] {logging_mixin.py:188} INFO - [2024-11-25T00:19:05.984+0000] {dagbag.py:545} INFO - Filling up the DagBag from /opt/airflow/dags/ETL_weather_hist.py
[2024-11-25T00:19:06.003+0000] {logging_mixin.py:188} INFO - [2024-11-25T00:19:05.997+0000] {dagbag.py:355} ERROR - Failed to import: /opt/airflow/dags/ETL_weather_hist.py
Traceback (most recent call last):
  File "/home/airflow/.local/lib/python3.12/site-packages/airflow/models/dagbag.py", line 351, in parse
    loader.exec_module(new_module)
  File "<frozen importlib._bootstrap_external>", line 995, in exec_module
  File "<frozen importlib._bootstrap>", line 488, in _call_with_frames_removed
  File "/opt/airflow/dags/ETL_weather_hist.py", line 102, in <module>
    extracted_df = extract_citibike_data(start_year, start_month, end_year, end_month)
                   ^^^^^^^^^^^^^^^^^^^^^
NameError: name 'extract_citibike_data' is not defined
[2024-11-25T00:19:06.006+0000] {processor.py:842} WARNING - No viable dags retrieved from /opt/airflow/dags/ETL_weather_hist.py
[2024-11-25T00:19:06.029+0000] {processor.py:183} INFO - Processing /opt/airflow/dags/ETL_weather_hist.py took 0.054 seconds
[2024-11-25T00:19:36.412+0000] {processor.py:161} INFO - Started process (PID=350) to work on /opt/airflow/dags/ETL_weather_hist.py
[2024-11-25T00:19:36.414+0000] {processor.py:830} INFO - Processing file /opt/airflow/dags/ETL_weather_hist.py for tasks to queue
[2024-11-25T00:19:36.416+0000] {logging_mixin.py:188} INFO - [2024-11-25T00:19:36.416+0000] {dagbag.py:545} INFO - Filling up the DagBag from /opt/airflow/dags/ETL_weather_hist.py
[2024-11-25T00:19:36.441+0000] {logging_mixin.py:188} INFO - [2024-11-25T00:19:36.435+0000] {dagbag.py:355} ERROR - Failed to import: /opt/airflow/dags/ETL_weather_hist.py
Traceback (most recent call last):
  File "/home/airflow/.local/lib/python3.12/site-packages/airflow/models/dagbag.py", line 351, in parse
    loader.exec_module(new_module)
  File "<frozen importlib._bootstrap_external>", line 995, in exec_module
  File "<frozen importlib._bootstrap>", line 488, in _call_with_frames_removed
  File "/opt/airflow/dags/ETL_weather_hist.py", line 102, in <module>
    extracted_df = extract_citibike_data(start_year, start_month, end_year, end_month)
                   ^^^^^^^^^^^^^^^^^^^^^
NameError: name 'extract_citibike_data' is not defined
[2024-11-25T00:19:36.444+0000] {processor.py:842} WARNING - No viable dags retrieved from /opt/airflow/dags/ETL_weather_hist.py
[2024-11-25T00:19:36.457+0000] {processor.py:183} INFO - Processing /opt/airflow/dags/ETL_weather_hist.py took 0.051 seconds
[2024-11-25T00:20:07.441+0000] {processor.py:161} INFO - Started process (PID=366) to work on /opt/airflow/dags/ETL_weather_hist.py
[2024-11-25T00:20:07.442+0000] {processor.py:830} INFO - Processing file /opt/airflow/dags/ETL_weather_hist.py for tasks to queue
[2024-11-25T00:20:07.444+0000] {logging_mixin.py:188} INFO - [2024-11-25T00:20:07.444+0000] {dagbag.py:545} INFO - Filling up the DagBag from /opt/airflow/dags/ETL_weather_hist.py
[2024-11-25T00:20:07.460+0000] {logging_mixin.py:188} INFO - [2024-11-25T00:20:07.455+0000] {dagbag.py:355} ERROR - Failed to import: /opt/airflow/dags/ETL_weather_hist.py
Traceback (most recent call last):
  File "/home/airflow/.local/lib/python3.12/site-packages/airflow/models/dagbag.py", line 351, in parse
    loader.exec_module(new_module)
  File "<frozen importlib._bootstrap_external>", line 995, in exec_module
  File "<frozen importlib._bootstrap>", line 488, in _call_with_frames_removed
  File "/opt/airflow/dags/ETL_weather_hist.py", line 102, in <module>
    extracted_df = extract_citibike_data(start_year, start_month, end_year, end_month)
                   ^^^^^^^^^^^^^^^^^^^^^
NameError: name 'extract_citibike_data' is not defined
[2024-11-25T00:20:07.463+0000] {processor.py:842} WARNING - No viable dags retrieved from /opt/airflow/dags/ETL_weather_hist.py
[2024-11-25T00:20:07.476+0000] {processor.py:183} INFO - Processing /opt/airflow/dags/ETL_weather_hist.py took 0.041 seconds
[2024-11-25T00:20:37.834+0000] {processor.py:161} INFO - Started process (PID=382) to work on /opt/airflow/dags/ETL_weather_hist.py
[2024-11-25T00:20:37.840+0000] {processor.py:830} INFO - Processing file /opt/airflow/dags/ETL_weather_hist.py for tasks to queue
[2024-11-25T00:20:37.841+0000] {logging_mixin.py:188} INFO - [2024-11-25T00:20:37.841+0000] {dagbag.py:545} INFO - Filling up the DagBag from /opt/airflow/dags/ETL_weather_hist.py
[2024-11-25T00:20:37.850+0000] {logging_mixin.py:188} INFO - [2024-11-25T00:20:37.847+0000] {dagbag.py:355} ERROR - Failed to import: /opt/airflow/dags/ETL_weather_hist.py
Traceback (most recent call last):
  File "/home/airflow/.local/lib/python3.12/site-packages/airflow/models/dagbag.py", line 351, in parse
    loader.exec_module(new_module)
  File "<frozen importlib._bootstrap_external>", line 995, in exec_module
  File "<frozen importlib._bootstrap>", line 488, in _call_with_frames_removed
  File "/opt/airflow/dags/ETL_weather_hist.py", line 102, in <module>
    extracted_df = extract_citibike_data(start_year, start_month, end_year, end_month)
                   ^^^^^^^^^^^^^^^^^^^^^
NameError: name 'extract_citibike_data' is not defined
[2024-11-25T00:20:37.853+0000] {processor.py:842} WARNING - No viable dags retrieved from /opt/airflow/dags/ETL_weather_hist.py
[2024-11-25T00:20:37.866+0000] {processor.py:183} INFO - Processing /opt/airflow/dags/ETL_weather_hist.py took 0.038 seconds
[2024-11-25T00:36:20.705+0000] {processor.py:161} INFO - Started process (PID=391) to work on /opt/airflow/dags/ETL_weather_hist.py
[2024-11-25T00:36:20.707+0000] {processor.py:830} INFO - Processing file /opt/airflow/dags/ETL_weather_hist.py for tasks to queue
[2024-11-25T00:36:20.709+0000] {logging_mixin.py:188} INFO - [2024-11-25T00:36:20.709+0000] {dagbag.py:545} INFO - Filling up the DagBag from /opt/airflow/dags/ETL_weather_hist.py
[2024-11-25T00:36:20.722+0000] {logging_mixin.py:188} INFO - [2024-11-25T00:36:20.719+0000] {dagbag.py:355} ERROR - Failed to import: /opt/airflow/dags/ETL_weather_hist.py
Traceback (most recent call last):
  File "/home/airflow/.local/lib/python3.12/site-packages/airflow/models/dagbag.py", line 351, in parse
    loader.exec_module(new_module)
  File "<frozen importlib._bootstrap_external>", line 995, in exec_module
  File "<frozen importlib._bootstrap>", line 488, in _call_with_frames_removed
  File "/opt/airflow/dags/ETL_weather_hist.py", line 102, in <module>
    extracted_df = extract_citibike_data(start_year, start_month, end_year, end_month)
                   ^^^^^^^^^^^^^^^^^^^^^
NameError: name 'extract_citibike_data' is not defined
[2024-11-25T00:36:20.725+0000] {processor.py:842} WARNING - No viable dags retrieved from /opt/airflow/dags/ETL_weather_hist.py
[2024-11-25T00:36:20.738+0000] {processor.py:183} INFO - Processing /opt/airflow/dags/ETL_weather_hist.py took 0.039 seconds
[2024-11-25T00:43:44.154+0000] {processor.py:161} INFO - Started process (PID=407) to work on /opt/airflow/dags/ETL_weather_hist.py
[2024-11-25T00:43:44.158+0000] {processor.py:830} INFO - Processing file /opt/airflow/dags/ETL_weather_hist.py for tasks to queue
[2024-11-25T00:43:44.161+0000] {logging_mixin.py:188} INFO - [2024-11-25T00:43:44.161+0000] {dagbag.py:545} INFO - Filling up the DagBag from /opt/airflow/dags/ETL_weather_hist.py
[2024-11-25T00:43:44.187+0000] {logging_mixin.py:188} INFO - [2024-11-25T00:43:44.180+0000] {dagbag.py:355} ERROR - Failed to import: /opt/airflow/dags/ETL_weather_hist.py
Traceback (most recent call last):
  File "/home/airflow/.local/lib/python3.12/site-packages/airflow/models/dagbag.py", line 351, in parse
    loader.exec_module(new_module)
  File "<frozen importlib._bootstrap_external>", line 995, in exec_module
  File "<frozen importlib._bootstrap>", line 488, in _call_with_frames_removed
  File "/opt/airflow/dags/ETL_weather_hist.py", line 102, in <module>
    extracted_df = extract_citibike_data(start_year, start_month, end_year, end_month)
                   ^^^^^^^^^^^^^^^^^^^^^
NameError: name 'extract_citibike_data' is not defined
[2024-11-25T00:43:44.192+0000] {processor.py:842} WARNING - No viable dags retrieved from /opt/airflow/dags/ETL_weather_hist.py
[2024-11-25T00:43:44.218+0000] {processor.py:183} INFO - Processing /opt/airflow/dags/ETL_weather_hist.py took 0.087 seconds
[2024-11-25T00:44:14.576+0000] {processor.py:161} INFO - Started process (PID=424) to work on /opt/airflow/dags/ETL_weather_hist.py
[2024-11-25T00:44:14.578+0000] {processor.py:830} INFO - Processing file /opt/airflow/dags/ETL_weather_hist.py for tasks to queue
[2024-11-25T00:44:14.583+0000] {logging_mixin.py:188} INFO - [2024-11-25T00:44:14.582+0000] {dagbag.py:545} INFO - Filling up the DagBag from /opt/airflow/dags/ETL_weather_hist.py
[2024-11-25T00:44:14.597+0000] {logging_mixin.py:188} INFO - [2024-11-25T00:44:14.593+0000] {dagbag.py:355} ERROR - Failed to import: /opt/airflow/dags/ETL_weather_hist.py
Traceback (most recent call last):
  File "/home/airflow/.local/lib/python3.12/site-packages/airflow/models/dagbag.py", line 351, in parse
    loader.exec_module(new_module)
  File "<frozen importlib._bootstrap_external>", line 995, in exec_module
  File "<frozen importlib._bootstrap>", line 488, in _call_with_frames_removed
  File "/opt/airflow/dags/ETL_weather_hist.py", line 102, in <module>
    extracted_df = extract_citibike_data(start_year, start_month, end_year, end_month)
                   ^^^^^^^^^^^^^^^^^^^^^
NameError: name 'extract_citibike_data' is not defined
[2024-11-25T00:44:14.600+0000] {processor.py:842} WARNING - No viable dags retrieved from /opt/airflow/dags/ETL_weather_hist.py
[2024-11-25T00:44:14.617+0000] {processor.py:183} INFO - Processing /opt/airflow/dags/ETL_weather_hist.py took 0.046 seconds
[2024-11-25T00:44:44.982+0000] {processor.py:161} INFO - Started process (PID=440) to work on /opt/airflow/dags/ETL_weather_hist.py
[2024-11-25T00:44:44.983+0000] {processor.py:830} INFO - Processing file /opt/airflow/dags/ETL_weather_hist.py for tasks to queue
[2024-11-25T00:44:44.984+0000] {logging_mixin.py:188} INFO - [2024-11-25T00:44:44.984+0000] {dagbag.py:545} INFO - Filling up the DagBag from /opt/airflow/dags/ETL_weather_hist.py
[2024-11-25T00:44:44.999+0000] {logging_mixin.py:188} INFO - [2024-11-25T00:44:44.994+0000] {dagbag.py:355} ERROR - Failed to import: /opt/airflow/dags/ETL_weather_hist.py
Traceback (most recent call last):
  File "/home/airflow/.local/lib/python3.12/site-packages/airflow/models/dagbag.py", line 351, in parse
    loader.exec_module(new_module)
  File "<frozen importlib._bootstrap_external>", line 995, in exec_module
  File "<frozen importlib._bootstrap>", line 488, in _call_with_frames_removed
  File "/opt/airflow/dags/ETL_weather_hist.py", line 102, in <module>
    extracted_df = extract_citibike_data(start_year, start_month, end_year, end_month)
                   ^^^^^^^^^^^^^^^^^^^^^
NameError: name 'extract_citibike_data' is not defined
[2024-11-25T00:44:45.002+0000] {processor.py:842} WARNING - No viable dags retrieved from /opt/airflow/dags/ETL_weather_hist.py
[2024-11-25T00:44:45.014+0000] {processor.py:183} INFO - Processing /opt/airflow/dags/ETL_weather_hist.py took 0.036 seconds
[2024-11-25T00:45:15.329+0000] {processor.py:161} INFO - Started process (PID=456) to work on /opt/airflow/dags/ETL_weather_hist.py
[2024-11-25T00:45:15.330+0000] {processor.py:830} INFO - Processing file /opt/airflow/dags/ETL_weather_hist.py for tasks to queue
[2024-11-25T00:45:15.331+0000] {logging_mixin.py:188} INFO - [2024-11-25T00:45:15.331+0000] {dagbag.py:545} INFO - Filling up the DagBag from /opt/airflow/dags/ETL_weather_hist.py
[2024-11-25T00:45:15.345+0000] {logging_mixin.py:188} INFO - [2024-11-25T00:45:15.339+0000] {dagbag.py:355} ERROR - Failed to import: /opt/airflow/dags/ETL_weather_hist.py
Traceback (most recent call last):
  File "/home/airflow/.local/lib/python3.12/site-packages/airflow/models/dagbag.py", line 351, in parse
    loader.exec_module(new_module)
  File "<frozen importlib._bootstrap_external>", line 995, in exec_module
  File "<frozen importlib._bootstrap>", line 488, in _call_with_frames_removed
  File "/opt/airflow/dags/ETL_weather_hist.py", line 102, in <module>
    extracted_df = extract_citibike_data(start_year, start_month, end_year, end_month)
                   ^^^^^^^^^^^^^^^^^^^^^
NameError: name 'extract_citibike_data' is not defined
[2024-11-25T00:45:15.347+0000] {processor.py:842} WARNING - No viable dags retrieved from /opt/airflow/dags/ETL_weather_hist.py
[2024-11-25T00:45:15.358+0000] {processor.py:183} INFO - Processing /opt/airflow/dags/ETL_weather_hist.py took 0.032 seconds
[2024-11-25T00:45:45.618+0000] {processor.py:161} INFO - Started process (PID=472) to work on /opt/airflow/dags/ETL_weather_hist.py
[2024-11-25T00:45:45.619+0000] {processor.py:830} INFO - Processing file /opt/airflow/dags/ETL_weather_hist.py for tasks to queue
[2024-11-25T00:45:45.621+0000] {logging_mixin.py:188} INFO - [2024-11-25T00:45:45.621+0000] {dagbag.py:545} INFO - Filling up the DagBag from /opt/airflow/dags/ETL_weather_hist.py
[2024-11-25T00:45:45.639+0000] {logging_mixin.py:188} INFO - [2024-11-25T00:45:45.634+0000] {dagbag.py:355} ERROR - Failed to import: /opt/airflow/dags/ETL_weather_hist.py
Traceback (most recent call last):
  File "/home/airflow/.local/lib/python3.12/site-packages/airflow/models/dagbag.py", line 351, in parse
    loader.exec_module(new_module)
  File "<frozen importlib._bootstrap_external>", line 995, in exec_module
  File "<frozen importlib._bootstrap>", line 488, in _call_with_frames_removed
  File "/opt/airflow/dags/ETL_weather_hist.py", line 102, in <module>
    extracted_df = extract_citibike_data(start_year, start_month, end_year, end_month)
                   ^^^^^^^^^^^^^^^^^^^^^
NameError: name 'extract_citibike_data' is not defined
[2024-11-25T00:45:45.642+0000] {processor.py:842} WARNING - No viable dags retrieved from /opt/airflow/dags/ETL_weather_hist.py
[2024-11-25T00:45:45.658+0000] {processor.py:183} INFO - Processing /opt/airflow/dags/ETL_weather_hist.py took 0.046 seconds
[2024-11-25T00:46:15.998+0000] {processor.py:161} INFO - Started process (PID=487) to work on /opt/airflow/dags/ETL_weather_hist.py
[2024-11-25T00:46:15.999+0000] {processor.py:830} INFO - Processing file /opt/airflow/dags/ETL_weather_hist.py for tasks to queue
[2024-11-25T00:46:16.001+0000] {logging_mixin.py:188} INFO - [2024-11-25T00:46:16.000+0000] {dagbag.py:545} INFO - Filling up the DagBag from /opt/airflow/dags/ETL_weather_hist.py
[2024-11-25T00:46:16.018+0000] {logging_mixin.py:188} INFO - [2024-11-25T00:46:16.012+0000] {dagbag.py:355} ERROR - Failed to import: /opt/airflow/dags/ETL_weather_hist.py
Traceback (most recent call last):
  File "/home/airflow/.local/lib/python3.12/site-packages/airflow/models/dagbag.py", line 351, in parse
    loader.exec_module(new_module)
  File "<frozen importlib._bootstrap_external>", line 995, in exec_module
  File "<frozen importlib._bootstrap>", line 488, in _call_with_frames_removed
  File "/opt/airflow/dags/ETL_weather_hist.py", line 102, in <module>
    extracted_df = extract_citibike_data(start_year, start_month, end_year, end_month)
                   ^^^^^^^^^^^^^^^^^^^^^
NameError: name 'extract_citibike_data' is not defined
[2024-11-25T00:46:16.023+0000] {processor.py:842} WARNING - No viable dags retrieved from /opt/airflow/dags/ETL_weather_hist.py
[2024-11-25T00:46:16.040+0000] {processor.py:183} INFO - Processing /opt/airflow/dags/ETL_weather_hist.py took 0.049 seconds
[2024-11-25T00:46:46.420+0000] {processor.py:161} INFO - Started process (PID=506) to work on /opt/airflow/dags/ETL_weather_hist.py
[2024-11-25T00:46:46.421+0000] {processor.py:830} INFO - Processing file /opt/airflow/dags/ETL_weather_hist.py for tasks to queue
[2024-11-25T00:46:46.423+0000] {logging_mixin.py:188} INFO - [2024-11-25T00:46:46.423+0000] {dagbag.py:545} INFO - Filling up the DagBag from /opt/airflow/dags/ETL_weather_hist.py
[2024-11-25T00:46:46.437+0000] {logging_mixin.py:188} INFO - [2024-11-25T00:46:46.433+0000] {dagbag.py:355} ERROR - Failed to import: /opt/airflow/dags/ETL_weather_hist.py
Traceback (most recent call last):
  File "/home/airflow/.local/lib/python3.12/site-packages/airflow/models/dagbag.py", line 351, in parse
    loader.exec_module(new_module)
  File "<frozen importlib._bootstrap_external>", line 995, in exec_module
  File "<frozen importlib._bootstrap>", line 488, in _call_with_frames_removed
  File "/opt/airflow/dags/ETL_weather_hist.py", line 102, in <module>
    extracted_df = extract_citibike_data(start_year, start_month, end_year, end_month)
                   ^^^^^^^^^^^^^^^^^^^^^
NameError: name 'extract_citibike_data' is not defined
[2024-11-25T00:46:46.440+0000] {processor.py:842} WARNING - No viable dags retrieved from /opt/airflow/dags/ETL_weather_hist.py
[2024-11-25T00:46:46.454+0000] {processor.py:183} INFO - Processing /opt/airflow/dags/ETL_weather_hist.py took 0.039 seconds
[2024-11-25T00:47:16.777+0000] {processor.py:161} INFO - Started process (PID=527) to work on /opt/airflow/dags/ETL_weather_hist.py
[2024-11-25T00:47:16.778+0000] {processor.py:830} INFO - Processing file /opt/airflow/dags/ETL_weather_hist.py for tasks to queue
[2024-11-25T00:47:16.780+0000] {logging_mixin.py:188} INFO - [2024-11-25T00:47:16.780+0000] {dagbag.py:545} INFO - Filling up the DagBag from /opt/airflow/dags/ETL_weather_hist.py
[2024-11-25T00:47:16.795+0000] {logging_mixin.py:188} INFO - [2024-11-25T00:47:16.791+0000] {dagbag.py:355} ERROR - Failed to import: /opt/airflow/dags/ETL_weather_hist.py
Traceback (most recent call last):
  File "/home/airflow/.local/lib/python3.12/site-packages/airflow/models/dagbag.py", line 351, in parse
    loader.exec_module(new_module)
  File "<frozen importlib._bootstrap_external>", line 995, in exec_module
  File "<frozen importlib._bootstrap>", line 488, in _call_with_frames_removed
  File "/opt/airflow/dags/ETL_weather_hist.py", line 102, in <module>
    extracted_df = extract_citibike_data(start_year, start_month, end_year, end_month)
                   ^^^^^^^^^^^^^^^^^^^^^
NameError: name 'extract_citibike_data' is not defined
[2024-11-25T00:47:16.798+0000] {processor.py:842} WARNING - No viable dags retrieved from /opt/airflow/dags/ETL_weather_hist.py
[2024-11-25T00:47:16.808+0000] {processor.py:183} INFO - Processing /opt/airflow/dags/ETL_weather_hist.py took 0.039 seconds
[2024-11-25T00:47:47.179+0000] {processor.py:161} INFO - Started process (PID=543) to work on /opt/airflow/dags/ETL_weather_hist.py
[2024-11-25T00:47:47.180+0000] {processor.py:830} INFO - Processing file /opt/airflow/dags/ETL_weather_hist.py for tasks to queue
[2024-11-25T00:47:47.181+0000] {logging_mixin.py:188} INFO - [2024-11-25T00:47:47.181+0000] {dagbag.py:545} INFO - Filling up the DagBag from /opt/airflow/dags/ETL_weather_hist.py
[2024-11-25T00:47:47.193+0000] {logging_mixin.py:188} INFO - [2024-11-25T00:47:47.189+0000] {dagbag.py:355} ERROR - Failed to import: /opt/airflow/dags/ETL_weather_hist.py
Traceback (most recent call last):
  File "/home/airflow/.local/lib/python3.12/site-packages/airflow/models/dagbag.py", line 351, in parse
    loader.exec_module(new_module)
  File "<frozen importlib._bootstrap_external>", line 995, in exec_module
  File "<frozen importlib._bootstrap>", line 488, in _call_with_frames_removed
  File "/opt/airflow/dags/ETL_weather_hist.py", line 102, in <module>
    extracted_df = extract_citibike_data(start_year, start_month, end_year, end_month)
                   ^^^^^^^^^^^^^^^^^^^^^
NameError: name 'extract_citibike_data' is not defined
[2024-11-25T00:47:47.196+0000] {processor.py:842} WARNING - No viable dags retrieved from /opt/airflow/dags/ETL_weather_hist.py
[2024-11-25T00:47:47.207+0000] {processor.py:183} INFO - Processing /opt/airflow/dags/ETL_weather_hist.py took 0.032 seconds
[2024-11-25T00:48:17.550+0000] {processor.py:161} INFO - Started process (PID=559) to work on /opt/airflow/dags/ETL_weather_hist.py
[2024-11-25T00:48:17.551+0000] {processor.py:830} INFO - Processing file /opt/airflow/dags/ETL_weather_hist.py for tasks to queue
[2024-11-25T00:48:17.553+0000] {logging_mixin.py:188} INFO - [2024-11-25T00:48:17.552+0000] {dagbag.py:545} INFO - Filling up the DagBag from /opt/airflow/dags/ETL_weather_hist.py
[2024-11-25T00:48:17.572+0000] {logging_mixin.py:188} INFO - [2024-11-25T00:48:17.568+0000] {dagbag.py:355} ERROR - Failed to import: /opt/airflow/dags/ETL_weather_hist.py
Traceback (most recent call last):
  File "/home/airflow/.local/lib/python3.12/site-packages/airflow/models/dagbag.py", line 351, in parse
    loader.exec_module(new_module)
  File "<frozen importlib._bootstrap_external>", line 995, in exec_module
  File "<frozen importlib._bootstrap>", line 488, in _call_with_frames_removed
  File "/opt/airflow/dags/ETL_weather_hist.py", line 102, in <module>
    extracted_df = extract_citibike_data(start_year, start_month, end_year, end_month)
                   ^^^^^^^^^^^^^^^^^^^^^
NameError: name 'extract_citibike_data' is not defined
[2024-11-25T00:48:17.575+0000] {processor.py:842} WARNING - No viable dags retrieved from /opt/airflow/dags/ETL_weather_hist.py
[2024-11-25T00:48:17.587+0000] {processor.py:183} INFO - Processing /opt/airflow/dags/ETL_weather_hist.py took 0.045 seconds
[2024-11-25T00:48:47.881+0000] {processor.py:161} INFO - Started process (PID=575) to work on /opt/airflow/dags/ETL_weather_hist.py
[2024-11-25T00:48:47.882+0000] {processor.py:830} INFO - Processing file /opt/airflow/dags/ETL_weather_hist.py for tasks to queue
[2024-11-25T00:48:47.883+0000] {logging_mixin.py:188} INFO - [2024-11-25T00:48:47.882+0000] {dagbag.py:545} INFO - Filling up the DagBag from /opt/airflow/dags/ETL_weather_hist.py
[2024-11-25T00:48:47.907+0000] {logging_mixin.py:188} INFO - [2024-11-25T00:48:47.904+0000] {dagbag.py:355} ERROR - Failed to import: /opt/airflow/dags/ETL_weather_hist.py
Traceback (most recent call last):
  File "/home/airflow/.local/lib/python3.12/site-packages/airflow/models/dagbag.py", line 351, in parse
    loader.exec_module(new_module)
  File "<frozen importlib._bootstrap_external>", line 995, in exec_module
  File "<frozen importlib._bootstrap>", line 488, in _call_with_frames_removed
  File "/opt/airflow/dags/ETL_weather_hist.py", line 102, in <module>
    extracted_df = extract_citibike_data(start_year, start_month, end_year, end_month)
                   ^^^^^^^^^^^^^^^^^^^^^
NameError: name 'extract_citibike_data' is not defined
[2024-11-25T00:48:47.910+0000] {processor.py:842} WARNING - No viable dags retrieved from /opt/airflow/dags/ETL_weather_hist.py
[2024-11-25T00:48:47.922+0000] {processor.py:183} INFO - Processing /opt/airflow/dags/ETL_weather_hist.py took 0.050 seconds
[2024-11-25T00:49:18.206+0000] {processor.py:161} INFO - Started process (PID=591) to work on /opt/airflow/dags/ETL_weather_hist.py
[2024-11-25T00:49:18.208+0000] {processor.py:830} INFO - Processing file /opt/airflow/dags/ETL_weather_hist.py for tasks to queue
[2024-11-25T00:49:18.209+0000] {logging_mixin.py:188} INFO - [2024-11-25T00:49:18.208+0000] {dagbag.py:545} INFO - Filling up the DagBag from /opt/airflow/dags/ETL_weather_hist.py
[2024-11-25T00:49:18.220+0000] {logging_mixin.py:188} INFO - [2024-11-25T00:49:18.216+0000] {dagbag.py:355} ERROR - Failed to import: /opt/airflow/dags/ETL_weather_hist.py
Traceback (most recent call last):
  File "/home/airflow/.local/lib/python3.12/site-packages/airflow/models/dagbag.py", line 351, in parse
    loader.exec_module(new_module)
  File "<frozen importlib._bootstrap_external>", line 995, in exec_module
  File "<frozen importlib._bootstrap>", line 488, in _call_with_frames_removed
  File "/opt/airflow/dags/ETL_weather_hist.py", line 102, in <module>
    extracted_df = extract_citibike_data(start_year, start_month, end_year, end_month)
                   ^^^^^^^^^^^^^^^^^^^^^
NameError: name 'extract_citibike_data' is not defined
[2024-11-25T00:49:18.223+0000] {processor.py:842} WARNING - No viable dags retrieved from /opt/airflow/dags/ETL_weather_hist.py
[2024-11-25T00:49:18.235+0000] {processor.py:183} INFO - Processing /opt/airflow/dags/ETL_weather_hist.py took 0.035 seconds
[2024-11-25T00:49:48.499+0000] {processor.py:161} INFO - Started process (PID=607) to work on /opt/airflow/dags/ETL_weather_hist.py
[2024-11-25T00:49:48.499+0000] {processor.py:830} INFO - Processing file /opt/airflow/dags/ETL_weather_hist.py for tasks to queue
[2024-11-25T00:49:48.500+0000] {logging_mixin.py:188} INFO - [2024-11-25T00:49:48.500+0000] {dagbag.py:545} INFO - Filling up the DagBag from /opt/airflow/dags/ETL_weather_hist.py
[2024-11-25T00:49:48.509+0000] {logging_mixin.py:188} INFO - [2024-11-25T00:49:48.506+0000] {dagbag.py:355} ERROR - Failed to import: /opt/airflow/dags/ETL_weather_hist.py
Traceback (most recent call last):
  File "/home/airflow/.local/lib/python3.12/site-packages/airflow/models/dagbag.py", line 351, in parse
    loader.exec_module(new_module)
  File "<frozen importlib._bootstrap_external>", line 995, in exec_module
  File "<frozen importlib._bootstrap>", line 488, in _call_with_frames_removed
  File "/opt/airflow/dags/ETL_weather_hist.py", line 102, in <module>
    extracted_df = extract_citibike_data(start_year, start_month, end_year, end_month)
                   ^^^^^^^^^^^^^^^^^^^^^
NameError: name 'extract_citibike_data' is not defined
[2024-11-25T00:49:48.511+0000] {processor.py:842} WARNING - No viable dags retrieved from /opt/airflow/dags/ETL_weather_hist.py
[2024-11-25T00:49:48.522+0000] {processor.py:183} INFO - Processing /opt/airflow/dags/ETL_weather_hist.py took 0.028 seconds
[2024-11-25T00:50:18.812+0000] {processor.py:161} INFO - Started process (PID=623) to work on /opt/airflow/dags/ETL_weather_hist.py
[2024-11-25T00:50:18.813+0000] {processor.py:830} INFO - Processing file /opt/airflow/dags/ETL_weather_hist.py for tasks to queue
[2024-11-25T00:50:18.814+0000] {logging_mixin.py:188} INFO - [2024-11-25T00:50:18.813+0000] {dagbag.py:545} INFO - Filling up the DagBag from /opt/airflow/dags/ETL_weather_hist.py
[2024-11-25T00:50:18.830+0000] {logging_mixin.py:188} INFO - [2024-11-25T00:50:18.826+0000] {dagbag.py:355} ERROR - Failed to import: /opt/airflow/dags/ETL_weather_hist.py
Traceback (most recent call last):
  File "/home/airflow/.local/lib/python3.12/site-packages/airflow/models/dagbag.py", line 351, in parse
    loader.exec_module(new_module)
  File "<frozen importlib._bootstrap_external>", line 995, in exec_module
  File "<frozen importlib._bootstrap>", line 488, in _call_with_frames_removed
  File "/opt/airflow/dags/ETL_weather_hist.py", line 102, in <module>
    extracted_df = extract_citibike_data(start_year, start_month, end_year, end_month)
                   ^^^^^^^^^^^^^^^^^^^^^
NameError: name 'extract_citibike_data' is not defined
[2024-11-25T00:50:18.833+0000] {processor.py:842} WARNING - No viable dags retrieved from /opt/airflow/dags/ETL_weather_hist.py
[2024-11-25T00:50:18.844+0000] {processor.py:183} INFO - Processing /opt/airflow/dags/ETL_weather_hist.py took 0.040 seconds
[2024-11-25T00:50:49.132+0000] {processor.py:161} INFO - Started process (PID=639) to work on /opt/airflow/dags/ETL_weather_hist.py
[2024-11-25T00:50:49.133+0000] {processor.py:830} INFO - Processing file /opt/airflow/dags/ETL_weather_hist.py for tasks to queue
[2024-11-25T00:50:49.133+0000] {logging_mixin.py:188} INFO - [2024-11-25T00:50:49.133+0000] {dagbag.py:545} INFO - Filling up the DagBag from /opt/airflow/dags/ETL_weather_hist.py
[2024-11-25T00:50:49.146+0000] {logging_mixin.py:188} INFO - [2024-11-25T00:50:49.142+0000] {dagbag.py:355} ERROR - Failed to import: /opt/airflow/dags/ETL_weather_hist.py
Traceback (most recent call last):
  File "/home/airflow/.local/lib/python3.12/site-packages/airflow/models/dagbag.py", line 351, in parse
    loader.exec_module(new_module)
  File "<frozen importlib._bootstrap_external>", line 995, in exec_module
  File "<frozen importlib._bootstrap>", line 488, in _call_with_frames_removed
  File "/opt/airflow/dags/ETL_weather_hist.py", line 102, in <module>
    extracted_df = extract_citibike_data(start_year, start_month, end_year, end_month)
                   ^^^^^^^^^^^^^^^^^^^^^
NameError: name 'extract_citibike_data' is not defined
[2024-11-25T00:50:49.149+0000] {processor.py:842} WARNING - No viable dags retrieved from /opt/airflow/dags/ETL_weather_hist.py
[2024-11-25T00:50:49.160+0000] {processor.py:183} INFO - Processing /opt/airflow/dags/ETL_weather_hist.py took 0.034 seconds
[2024-11-25T00:51:19.471+0000] {processor.py:161} INFO - Started process (PID=655) to work on /opt/airflow/dags/ETL_weather_hist.py
[2024-11-25T00:51:19.472+0000] {processor.py:830} INFO - Processing file /opt/airflow/dags/ETL_weather_hist.py for tasks to queue
[2024-11-25T00:51:19.473+0000] {logging_mixin.py:188} INFO - [2024-11-25T00:51:19.473+0000] {dagbag.py:545} INFO - Filling up the DagBag from /opt/airflow/dags/ETL_weather_hist.py
[2024-11-25T00:51:19.488+0000] {logging_mixin.py:188} INFO - [2024-11-25T00:51:19.484+0000] {dagbag.py:355} ERROR - Failed to import: /opt/airflow/dags/ETL_weather_hist.py
Traceback (most recent call last):
  File "/home/airflow/.local/lib/python3.12/site-packages/airflow/models/dagbag.py", line 351, in parse
    loader.exec_module(new_module)
  File "<frozen importlib._bootstrap_external>", line 995, in exec_module
  File "<frozen importlib._bootstrap>", line 488, in _call_with_frames_removed
  File "/opt/airflow/dags/ETL_weather_hist.py", line 102, in <module>
    extracted_df = extract_citibike_data(start_year, start_month, end_year, end_month)
                   ^^^^^^^^^^^^^^^^^^^^^
NameError: name 'extract_citibike_data' is not defined
[2024-11-25T00:51:19.492+0000] {processor.py:842} WARNING - No viable dags retrieved from /opt/airflow/dags/ETL_weather_hist.py
[2024-11-25T00:51:19.506+0000] {processor.py:183} INFO - Processing /opt/airflow/dags/ETL_weather_hist.py took 0.039 seconds
[2024-11-25T00:51:49.807+0000] {processor.py:161} INFO - Started process (PID=671) to work on /opt/airflow/dags/ETL_weather_hist.py
[2024-11-25T00:51:49.808+0000] {processor.py:830} INFO - Processing file /opt/airflow/dags/ETL_weather_hist.py for tasks to queue
[2024-11-25T00:51:49.808+0000] {logging_mixin.py:188} INFO - [2024-11-25T00:51:49.808+0000] {dagbag.py:545} INFO - Filling up the DagBag from /opt/airflow/dags/ETL_weather_hist.py
[2024-11-25T00:51:49.823+0000] {logging_mixin.py:188} INFO - [2024-11-25T00:51:49.819+0000] {dagbag.py:355} ERROR - Failed to import: /opt/airflow/dags/ETL_weather_hist.py
Traceback (most recent call last):
  File "/home/airflow/.local/lib/python3.12/site-packages/airflow/models/dagbag.py", line 351, in parse
    loader.exec_module(new_module)
  File "<frozen importlib._bootstrap_external>", line 995, in exec_module
  File "<frozen importlib._bootstrap>", line 488, in _call_with_frames_removed
  File "/opt/airflow/dags/ETL_weather_hist.py", line 102, in <module>
    extracted_df = extract_citibike_data(start_year, start_month, end_year, end_month)
                   ^^^^^^^^^^^^^^^^^^^^^
NameError: name 'extract_citibike_data' is not defined
[2024-11-25T00:51:49.826+0000] {processor.py:842} WARNING - No viable dags retrieved from /opt/airflow/dags/ETL_weather_hist.py
[2024-11-25T00:51:49.836+0000] {processor.py:183} INFO - Processing /opt/airflow/dags/ETL_weather_hist.py took 0.035 seconds
[2024-11-25T00:52:20.189+0000] {processor.py:161} INFO - Started process (PID=687) to work on /opt/airflow/dags/ETL_weather_hist.py
[2024-11-25T00:52:20.190+0000] {processor.py:830} INFO - Processing file /opt/airflow/dags/ETL_weather_hist.py for tasks to queue
[2024-11-25T00:52:20.191+0000] {logging_mixin.py:188} INFO - [2024-11-25T00:52:20.191+0000] {dagbag.py:545} INFO - Filling up the DagBag from /opt/airflow/dags/ETL_weather_hist.py
[2024-11-25T00:52:20.205+0000] {logging_mixin.py:188} INFO - [2024-11-25T00:52:20.201+0000] {dagbag.py:355} ERROR - Failed to import: /opt/airflow/dags/ETL_weather_hist.py
Traceback (most recent call last):
  File "/home/airflow/.local/lib/python3.12/site-packages/airflow/models/dagbag.py", line 351, in parse
    loader.exec_module(new_module)
  File "<frozen importlib._bootstrap_external>", line 995, in exec_module
  File "<frozen importlib._bootstrap>", line 488, in _call_with_frames_removed
  File "/opt/airflow/dags/ETL_weather_hist.py", line 102, in <module>
    extracted_df = extract_citibike_data(start_year, start_month, end_year, end_month)
                   ^^^^^^^^^^^^^^^^^^^^^
NameError: name 'extract_citibike_data' is not defined
[2024-11-25T00:52:20.208+0000] {processor.py:842} WARNING - No viable dags retrieved from /opt/airflow/dags/ETL_weather_hist.py
[2024-11-25T00:52:20.221+0000] {processor.py:183} INFO - Processing /opt/airflow/dags/ETL_weather_hist.py took 0.041 seconds
[2024-11-25T00:52:50.545+0000] {processor.py:161} INFO - Started process (PID=709) to work on /opt/airflow/dags/ETL_weather_hist.py
[2024-11-25T00:52:50.545+0000] {processor.py:830} INFO - Processing file /opt/airflow/dags/ETL_weather_hist.py for tasks to queue
[2024-11-25T00:52:50.546+0000] {logging_mixin.py:188} INFO - [2024-11-25T00:52:50.546+0000] {dagbag.py:545} INFO - Filling up the DagBag from /opt/airflow/dags/ETL_weather_hist.py
[2024-11-25T00:52:50.558+0000] {logging_mixin.py:188} INFO - [2024-11-25T00:52:50.555+0000] {dagbag.py:355} ERROR - Failed to import: /opt/airflow/dags/ETL_weather_hist.py
Traceback (most recent call last):
  File "/home/airflow/.local/lib/python3.12/site-packages/airflow/models/dagbag.py", line 351, in parse
    loader.exec_module(new_module)
  File "<frozen importlib._bootstrap_external>", line 995, in exec_module
  File "<frozen importlib._bootstrap>", line 488, in _call_with_frames_removed
  File "/opt/airflow/dags/ETL_weather_hist.py", line 102, in <module>
    extracted_df = extract_citibike_data(start_year, start_month, end_year, end_month)
                   ^^^^^^^^^^^^^^^^^^^^^
NameError: name 'extract_citibike_data' is not defined
[2024-11-25T00:52:50.561+0000] {processor.py:842} WARNING - No viable dags retrieved from /opt/airflow/dags/ETL_weather_hist.py
[2024-11-25T00:52:50.575+0000] {processor.py:183} INFO - Processing /opt/airflow/dags/ETL_weather_hist.py took 0.036 seconds
[2024-11-25T00:53:20.885+0000] {processor.py:161} INFO - Started process (PID=725) to work on /opt/airflow/dags/ETL_weather_hist.py
[2024-11-25T00:53:20.887+0000] {processor.py:830} INFO - Processing file /opt/airflow/dags/ETL_weather_hist.py for tasks to queue
[2024-11-25T00:53:20.889+0000] {logging_mixin.py:188} INFO - [2024-11-25T00:53:20.888+0000] {dagbag.py:545} INFO - Filling up the DagBag from /opt/airflow/dags/ETL_weather_hist.py
[2024-11-25T00:53:20.903+0000] {logging_mixin.py:188} INFO - [2024-11-25T00:53:20.900+0000] {dagbag.py:355} ERROR - Failed to import: /opt/airflow/dags/ETL_weather_hist.py
Traceback (most recent call last):
  File "/home/airflow/.local/lib/python3.12/site-packages/airflow/models/dagbag.py", line 351, in parse
    loader.exec_module(new_module)
  File "<frozen importlib._bootstrap_external>", line 995, in exec_module
  File "<frozen importlib._bootstrap>", line 488, in _call_with_frames_removed
  File "/opt/airflow/dags/ETL_weather_hist.py", line 102, in <module>
    extracted_df = extract_citibike_data(start_year, start_month, end_year, end_month)
                   ^^^^^^^^^^^^^^^^^^^^^
NameError: name 'extract_citibike_data' is not defined
[2024-11-25T00:53:20.906+0000] {processor.py:842} WARNING - No viable dags retrieved from /opt/airflow/dags/ETL_weather_hist.py
[2024-11-25T00:53:20.917+0000] {processor.py:183} INFO - Processing /opt/airflow/dags/ETL_weather_hist.py took 0.038 seconds
[2024-11-25T00:53:51.232+0000] {processor.py:161} INFO - Started process (PID=741) to work on /opt/airflow/dags/ETL_weather_hist.py
[2024-11-25T00:53:51.233+0000] {processor.py:830} INFO - Processing file /opt/airflow/dags/ETL_weather_hist.py for tasks to queue
[2024-11-25T00:53:51.234+0000] {logging_mixin.py:188} INFO - [2024-11-25T00:53:51.234+0000] {dagbag.py:545} INFO - Filling up the DagBag from /opt/airflow/dags/ETL_weather_hist.py
[2024-11-25T00:53:51.245+0000] {logging_mixin.py:188} INFO - [2024-11-25T00:53:51.242+0000] {dagbag.py:355} ERROR - Failed to import: /opt/airflow/dags/ETL_weather_hist.py
Traceback (most recent call last):
  File "/home/airflow/.local/lib/python3.12/site-packages/airflow/models/dagbag.py", line 351, in parse
    loader.exec_module(new_module)
  File "<frozen importlib._bootstrap_external>", line 995, in exec_module
  File "<frozen importlib._bootstrap>", line 488, in _call_with_frames_removed
  File "/opt/airflow/dags/ETL_weather_hist.py", line 102, in <module>
    extracted_df = extract_citibike_data(start_year, start_month, end_year, end_month)
                   ^^^^^^^^^^^^^^^^^^^^^
NameError: name 'extract_citibike_data' is not defined
[2024-11-25T00:53:51.249+0000] {processor.py:842} WARNING - No viable dags retrieved from /opt/airflow/dags/ETL_weather_hist.py
[2024-11-25T00:53:51.262+0000] {processor.py:183} INFO - Processing /opt/airflow/dags/ETL_weather_hist.py took 0.034 seconds
[2024-11-25T00:54:21.571+0000] {processor.py:161} INFO - Started process (PID=756) to work on /opt/airflow/dags/ETL_weather_hist.py
[2024-11-25T00:54:21.574+0000] {processor.py:830} INFO - Processing file /opt/airflow/dags/ETL_weather_hist.py for tasks to queue
[2024-11-25T00:54:21.575+0000] {logging_mixin.py:188} INFO - [2024-11-25T00:54:21.574+0000] {dagbag.py:545} INFO - Filling up the DagBag from /opt/airflow/dags/ETL_weather_hist.py
[2024-11-25T00:54:21.590+0000] {logging_mixin.py:188} INFO - [2024-11-25T00:54:21.586+0000] {dagbag.py:355} ERROR - Failed to import: /opt/airflow/dags/ETL_weather_hist.py
Traceback (most recent call last):
  File "/home/airflow/.local/lib/python3.12/site-packages/airflow/models/dagbag.py", line 351, in parse
    loader.exec_module(new_module)
  File "<frozen importlib._bootstrap_external>", line 995, in exec_module
  File "<frozen importlib._bootstrap>", line 488, in _call_with_frames_removed
  File "/opt/airflow/dags/ETL_weather_hist.py", line 102, in <module>
    extracted_df = extract_citibike_data(start_year, start_month, end_year, end_month)
                   ^^^^^^^^^^^^^^^^^^^^^
NameError: name 'extract_citibike_data' is not defined
[2024-11-25T00:54:21.593+0000] {processor.py:842} WARNING - No viable dags retrieved from /opt/airflow/dags/ETL_weather_hist.py
[2024-11-25T00:54:21.603+0000] {processor.py:183} INFO - Processing /opt/airflow/dags/ETL_weather_hist.py took 0.038 seconds
[2024-11-25T00:54:51.984+0000] {processor.py:161} INFO - Started process (PID=777) to work on /opt/airflow/dags/ETL_weather_hist.py
[2024-11-25T00:54:51.985+0000] {processor.py:830} INFO - Processing file /opt/airflow/dags/ETL_weather_hist.py for tasks to queue
[2024-11-25T00:54:51.986+0000] {logging_mixin.py:188} INFO - [2024-11-25T00:54:51.985+0000] {dagbag.py:545} INFO - Filling up the DagBag from /opt/airflow/dags/ETL_weather_hist.py
[2024-11-25T00:54:52.000+0000] {logging_mixin.py:188} INFO - [2024-11-25T00:54:51.997+0000] {dagbag.py:355} ERROR - Failed to import: /opt/airflow/dags/ETL_weather_hist.py
Traceback (most recent call last):
  File "/home/airflow/.local/lib/python3.12/site-packages/airflow/models/dagbag.py", line 351, in parse
    loader.exec_module(new_module)
  File "<frozen importlib._bootstrap_external>", line 995, in exec_module
  File "<frozen importlib._bootstrap>", line 488, in _call_with_frames_removed
  File "/opt/airflow/dags/ETL_weather_hist.py", line 102, in <module>
    extracted_df = extract_citibike_data(start_year, start_month, end_year, end_month)
                   ^^^^^^^^^^^^^^^^^^^^^
NameError: name 'extract_citibike_data' is not defined
[2024-11-25T00:54:52.003+0000] {processor.py:842} WARNING - No viable dags retrieved from /opt/airflow/dags/ETL_weather_hist.py
[2024-11-25T00:54:52.014+0000] {processor.py:183} INFO - Processing /opt/airflow/dags/ETL_weather_hist.py took 0.037 seconds
[2024-11-25T00:55:22.302+0000] {processor.py:161} INFO - Started process (PID=793) to work on /opt/airflow/dags/ETL_weather_hist.py
[2024-11-25T00:55:22.302+0000] {processor.py:830} INFO - Processing file /opt/airflow/dags/ETL_weather_hist.py for tasks to queue
[2024-11-25T00:55:22.303+0000] {logging_mixin.py:188} INFO - [2024-11-25T00:55:22.303+0000] {dagbag.py:545} INFO - Filling up the DagBag from /opt/airflow/dags/ETL_weather_hist.py
[2024-11-25T00:55:22.312+0000] {logging_mixin.py:188} INFO - [2024-11-25T00:55:22.309+0000] {dagbag.py:355} ERROR - Failed to import: /opt/airflow/dags/ETL_weather_hist.py
Traceback (most recent call last):
  File "/home/airflow/.local/lib/python3.12/site-packages/airflow/models/dagbag.py", line 351, in parse
    loader.exec_module(new_module)
  File "<frozen importlib._bootstrap_external>", line 995, in exec_module
  File "<frozen importlib._bootstrap>", line 488, in _call_with_frames_removed
  File "/opt/airflow/dags/ETL_weather_hist.py", line 102, in <module>
    extracted_df = extract_citibike_data(start_year, start_month, end_year, end_month)
                   ^^^^^^^^^^^^^^^^^^^^^
NameError: name 'extract_citibike_data' is not defined
[2024-11-25T00:55:22.314+0000] {processor.py:842} WARNING - No viable dags retrieved from /opt/airflow/dags/ETL_weather_hist.py
[2024-11-25T00:55:22.324+0000] {processor.py:183} INFO - Processing /opt/airflow/dags/ETL_weather_hist.py took 0.027 seconds
[2024-11-25T00:55:52.651+0000] {processor.py:161} INFO - Started process (PID=814) to work on /opt/airflow/dags/ETL_weather_hist.py
[2024-11-25T00:55:52.652+0000] {processor.py:830} INFO - Processing file /opt/airflow/dags/ETL_weather_hist.py for tasks to queue
[2024-11-25T00:55:52.653+0000] {logging_mixin.py:188} INFO - [2024-11-25T00:55:52.653+0000] {dagbag.py:545} INFO - Filling up the DagBag from /opt/airflow/dags/ETL_weather_hist.py
[2024-11-25T00:55:52.670+0000] {logging_mixin.py:188} INFO - [2024-11-25T00:55:52.665+0000] {dagbag.py:355} ERROR - Failed to import: /opt/airflow/dags/ETL_weather_hist.py
Traceback (most recent call last):
  File "/home/airflow/.local/lib/python3.12/site-packages/airflow/models/dagbag.py", line 351, in parse
    loader.exec_module(new_module)
  File "<frozen importlib._bootstrap_external>", line 995, in exec_module
  File "<frozen importlib._bootstrap>", line 488, in _call_with_frames_removed
  File "/opt/airflow/dags/ETL_weather_hist.py", line 102, in <module>
    extracted_df = extract_citibike_data(start_year, start_month, end_year, end_month)
                   ^^^^^^^^^^^^^^^^^^^^^
NameError: name 'extract_citibike_data' is not defined
[2024-11-25T00:55:52.673+0000] {processor.py:842} WARNING - No viable dags retrieved from /opt/airflow/dags/ETL_weather_hist.py
[2024-11-25T00:55:52.684+0000] {processor.py:183} INFO - Processing /opt/airflow/dags/ETL_weather_hist.py took 0.041 seconds
[2024-11-25T00:56:22.998+0000] {processor.py:161} INFO - Started process (PID=831) to work on /opt/airflow/dags/ETL_weather_hist.py
[2024-11-25T00:56:22.999+0000] {processor.py:830} INFO - Processing file /opt/airflow/dags/ETL_weather_hist.py for tasks to queue
[2024-11-25T00:56:22.999+0000] {logging_mixin.py:188} INFO - [2024-11-25T00:56:22.999+0000] {dagbag.py:545} INFO - Filling up the DagBag from /opt/airflow/dags/ETL_weather_hist.py
[2024-11-25T00:56:23.009+0000] {logging_mixin.py:188} INFO - [2024-11-25T00:56:23.006+0000] {dagbag.py:355} ERROR - Failed to import: /opt/airflow/dags/ETL_weather_hist.py
Traceback (most recent call last):
  File "/home/airflow/.local/lib/python3.12/site-packages/airflow/models/dagbag.py", line 351, in parse
    loader.exec_module(new_module)
  File "<frozen importlib._bootstrap_external>", line 995, in exec_module
  File "<frozen importlib._bootstrap>", line 488, in _call_with_frames_removed
  File "/opt/airflow/dags/ETL_weather_hist.py", line 102, in <module>
    extracted_df = extract_citibike_data(start_year, start_month, end_year, end_month)
                   ^^^^^^^^^^^^^^^^^^^^^
NameError: name 'extract_citibike_data' is not defined
[2024-11-25T00:56:23.011+0000] {processor.py:842} WARNING - No viable dags retrieved from /opt/airflow/dags/ETL_weather_hist.py
[2024-11-25T00:56:23.022+0000] {processor.py:183} INFO - Processing /opt/airflow/dags/ETL_weather_hist.py took 0.028 seconds
