[2024-12-05T20:06:06.714+0000] {local_task_job_runner.py:120} INFO - ::group::Pre task execution logs
[2024-12-05T20:06:06.730+0000] {taskinstance.py:2076} INFO - Dependencies all met for dep_context=non-requeueable deps ti=<TaskInstance: ELT_dbt.dbt_run manual__2024-12-05T20:06:05.998646+00:00 [queued]>
[2024-12-05T20:06:06.733+0000] {taskinstance.py:2076} INFO - Dependencies all met for dep_context=requeueable deps ti=<TaskInstance: ELT_dbt.dbt_run manual__2024-12-05T20:06:05.998646+00:00 [queued]>
[2024-12-05T20:06:06.733+0000] {taskinstance.py:2306} INFO - Starting attempt 1 of 1
[2024-12-05T20:06:06.739+0000] {taskinstance.py:2330} INFO - Executing <Task(BashOperator): dbt_run> on 2024-12-05 20:06:05.998646+00:00
[2024-12-05T20:06:06.745+0000] {logging_mixin.py:188} WARNING - /home/***/.local/lib/python3.12/site-packages/***/task/task_runner/standard_task_runner.py:61 DeprecationWarning: This process (pid=1816) is multi-threaded, use of fork() may lead to deadlocks in the child.
[2024-12-05T20:06:06.744+0000] {standard_task_runner.py:90} INFO - Running: ['***', 'tasks', 'run', 'ELT_dbt', 'dbt_run', 'manual__2024-12-05T20:06:05.998646+00:00', '--job-id', '491', '--raw', '--subdir', 'DAGS_FOLDER/ELT_metrics.py', '--cfg-path', '/tmp/tmpxitb4rr2']
[2024-12-05T20:06:06.745+0000] {standard_task_runner.py:63} INFO - Started process 1823 to run task
[2024-12-05T20:06:06.746+0000] {standard_task_runner.py:91} INFO - Job 491: Subtask dbt_run
[2024-12-05T20:06:06.770+0000] {task_command.py:426} INFO - Running <TaskInstance: ELT_dbt.dbt_run manual__2024-12-05T20:06:05.998646+00:00 [running]> on host 54099fe05abe
[2024-12-05T20:06:06.812+0000] {taskinstance.py:2648} INFO - Exporting env vars: AIRFLOW_CTX_DAG_OWNER='***' AIRFLOW_CTX_DAG_ID='ELT_dbt' AIRFLOW_CTX_TASK_ID='dbt_run' AIRFLOW_CTX_EXECUTION_DATE='2024-12-05T20:06:05.998646+00:00' AIRFLOW_CTX_TRY_NUMBER='1' AIRFLOW_CTX_DAG_RUN_ID='manual__2024-12-05T20:06:05.998646+00:00'
[2024-12-05T20:06:06.812+0000] {taskinstance.py:430} INFO - ::endgroup::
[2024-12-05T20:06:06.821+0000] {subprocess.py:63} INFO - Tmp dir root location: /tmp
[2024-12-05T20:06:06.822+0000] {subprocess.py:75} INFO - Running command: ['/usr/bin/bash', '-c', '/home/***/.local/bin/dbt run --profiles-dir /opt/***/dbt_proj --project-dir /opt/***/dbt_proj']
[2024-12-05T20:06:06.829+0000] {subprocess.py:86} INFO - Output:
[2024-12-05T20:06:08.062+0000] {subprocess.py:93} INFO - [0m20:06:08  Running with dbt=1.8.7
[2024-12-05T20:06:08.062+0000] {subprocess.py:93} INFO - [0m20:06:08  Encountered an error:
[2024-12-05T20:06:08.063+0000] {subprocess.py:93} INFO - Runtime Error
[2024-12-05T20:06:08.063+0000] {subprocess.py:93} INFO -   No dbt_project.yml found at expected path /opt/***/dbt_proj/dbt_project.yml
[2024-12-05T20:06:08.063+0000] {subprocess.py:93} INFO -   Verify that each entry within packages.yml (and their transitive dependencies) contains a file named dbt_project.yml
[2024-12-05T20:06:08.063+0000] {subprocess.py:93} INFO - 
[2024-12-05T20:06:08.611+0000] {subprocess.py:97} INFO - Command exited with return code 2
[2024-12-05T20:06:08.612+0000] {taskinstance.py:441} INFO - ::group::Post task execution logs
[2024-12-05T20:06:08.619+0000] {taskinstance.py:2905} ERROR - Task failed with exception
Traceback (most recent call last):
  File "/home/airflow/.local/lib/python3.12/site-packages/airflow/models/taskinstance.py", line 465, in _execute_task
    result = _execute_callable(context=context, **execute_callable_kwargs)
             ^^^^^^^^^^^^^^^^^^^^^^^^^^^^^^^^^^^^^^^^^^^^^^^^^^^^^^^^^^^^^
  File "/home/airflow/.local/lib/python3.12/site-packages/airflow/models/taskinstance.py", line 432, in _execute_callable
    return execute_callable(context=context, **execute_callable_kwargs)
           ^^^^^^^^^^^^^^^^^^^^^^^^^^^^^^^^^^^^^^^^^^^^^^^^^^^^^^^^^^^^
  File "/home/airflow/.local/lib/python3.12/site-packages/airflow/models/baseoperator.py", line 400, in wrapper
    return func(self, *args, **kwargs)
           ^^^^^^^^^^^^^^^^^^^^^^^^^^^
  File "/home/airflow/.local/lib/python3.12/site-packages/airflow/operators/bash.py", line 243, in execute
    raise AirflowException(
airflow.exceptions.AirflowException: Bash command failed. The command returned a non-zero exit code 2.
[2024-12-05T20:06:08.622+0000] {taskinstance.py:1206} INFO - Marking task as FAILED. dag_id=ELT_dbt, task_id=dbt_run, run_id=manual__2024-12-05T20:06:05.998646+00:00, execution_date=20241205T200605, start_date=20241205T200606, end_date=20241205T200608
[2024-12-05T20:06:08.629+0000] {standard_task_runner.py:110} ERROR - Failed to execute job 491 for task dbt_run (Bash command failed. The command returned a non-zero exit code 2.; 1823)
[2024-12-05T20:06:08.665+0000] {local_task_job_runner.py:240} INFO - Task exited with return code 1
[2024-12-05T20:06:08.679+0000] {taskinstance.py:3498} INFO - 0 downstream tasks scheduled from follow-on schedule check
[2024-12-05T20:06:08.681+0000] {local_task_job_runner.py:222} INFO - ::endgroup::
