[2024-12-05T20:05:55.600+0000] {local_task_job_runner.py:120} INFO - ::group::Pre task execution logs
[2024-12-05T20:05:55.620+0000] {taskinstance.py:2076} INFO - Dependencies all met for dep_context=non-requeueable deps ti=<TaskInstance: ELT_dbt.dbt_run manual__2024-12-05T20:03:06.405696+00:00 [queued]>
[2024-12-05T20:05:55.624+0000] {taskinstance.py:2076} INFO - Dependencies all met for dep_context=requeueable deps ti=<TaskInstance: ELT_dbt.dbt_run manual__2024-12-05T20:03:06.405696+00:00 [queued]>
[2024-12-05T20:05:55.625+0000] {taskinstance.py:2306} INFO - Starting attempt 2 of 2
[2024-12-05T20:05:55.631+0000] {taskinstance.py:2330} INFO - Executing <Task(BashOperator): dbt_run> on 2024-12-05 20:03:06.405696+00:00
[2024-12-05T20:05:55.640+0000] {logging_mixin.py:188} WARNING - /home/***/.local/lib/python3.12/site-packages/***/task/task_runner/standard_task_runner.py:61 DeprecationWarning: This process (pid=1777) is multi-threaded, use of fork() may lead to deadlocks in the child.
[2024-12-05T20:05:55.635+0000] {standard_task_runner.py:90} INFO - Running: ['***', 'tasks', 'run', 'ELT_dbt', 'dbt_run', 'manual__2024-12-05T20:03:06.405696+00:00', '--job-id', '486', '--raw', '--subdir', 'DAGS_FOLDER/ELT_metrics.py', '--cfg-path', '/tmp/tmpg7up201y']
[2024-12-05T20:05:55.641+0000] {standard_task_runner.py:91} INFO - Job 486: Subtask dbt_run
[2024-12-05T20:05:55.641+0000] {standard_task_runner.py:63} INFO - Started process 1778 to run task
[2024-12-05T20:05:55.671+0000] {task_command.py:426} INFO - Running <TaskInstance: ELT_dbt.dbt_run manual__2024-12-05T20:03:06.405696+00:00 [running]> on host 54099fe05abe
[2024-12-05T20:05:55.719+0000] {taskinstance.py:2648} INFO - Exporting env vars: AIRFLOW_CTX_DAG_OWNER='***' AIRFLOW_CTX_DAG_ID='ELT_dbt' AIRFLOW_CTX_TASK_ID='dbt_run' AIRFLOW_CTX_EXECUTION_DATE='2024-12-05T20:03:06.405696+00:00' AIRFLOW_CTX_TRY_NUMBER='2' AIRFLOW_CTX_DAG_RUN_ID='manual__2024-12-05T20:03:06.405696+00:00'
[2024-12-05T20:05:55.720+0000] {taskinstance.py:430} INFO - ::endgroup::
[2024-12-05T20:05:55.729+0000] {subprocess.py:63} INFO - Tmp dir root location: /tmp
[2024-12-05T20:05:55.730+0000] {subprocess.py:75} INFO - Running command: ['/usr/bin/bash', '-c', '/home/***/.local/bin/dbt run --profiles-dir /opt/***/dbt_proj --project-dir /opt/***/dbt_proj']
[2024-12-05T20:05:55.736+0000] {subprocess.py:86} INFO - Output:
[2024-12-05T20:05:57.103+0000] {subprocess.py:93} INFO - [0m20:05:57  Running with dbt=1.8.7
[2024-12-05T20:05:57.103+0000] {subprocess.py:93} INFO - [0m20:05:57  Encountered an error:
[2024-12-05T20:05:57.104+0000] {subprocess.py:93} INFO - Runtime Error
[2024-12-05T20:05:57.104+0000] {subprocess.py:93} INFO -   No dbt_project.yml found at expected path /opt/***/dbt_proj/dbt_project.yml
[2024-12-05T20:05:57.104+0000] {subprocess.py:93} INFO -   Verify that each entry within packages.yml (and their transitive dependencies) contains a file named dbt_project.yml
[2024-12-05T20:05:57.104+0000] {subprocess.py:93} INFO - 
[2024-12-05T20:05:57.643+0000] {subprocess.py:97} INFO - Command exited with return code 2
[2024-12-05T20:05:57.644+0000] {taskinstance.py:441} INFO - ::group::Post task execution logs
[2024-12-05T20:05:57.650+0000] {taskinstance.py:2905} ERROR - Task failed with exception
Traceback (most recent call last):
  File "/home/airflow/.local/lib/python3.12/site-packages/airflow/models/taskinstance.py", line 465, in _execute_task
    result = _execute_callable(context=context, **execute_callable_kwargs)
             ^^^^^^^^^^^^^^^^^^^^^^^^^^^^^^^^^^^^^^^^^^^^^^^^^^^^^^^^^^^^^
  File "/home/airflow/.local/lib/python3.12/site-packages/airflow/models/taskinstance.py", line 432, in _execute_callable
    return execute_callable(context=context, **execute_callable_kwargs)
           ^^^^^^^^^^^^^^^^^^^^^^^^^^^^^^^^^^^^^^^^^^^^^^^^^^^^^^^^^^^^
  File "/home/airflow/.local/lib/python3.12/site-packages/airflow/models/baseoperator.py", line 400, in wrapper
    return func(self, *args, **kwargs)
           ^^^^^^^^^^^^^^^^^^^^^^^^^^^
  File "/home/airflow/.local/lib/python3.12/site-packages/airflow/operators/bash.py", line 243, in execute
    raise AirflowException(
airflow.exceptions.AirflowException: Bash command failed. The command returned a non-zero exit code 2.
[2024-12-05T20:05:57.653+0000] {taskinstance.py:1206} INFO - Marking task as FAILED. dag_id=ELT_dbt, task_id=dbt_run, run_id=manual__2024-12-05T20:03:06.405696+00:00, execution_date=20241205T200306, start_date=20241205T200555, end_date=20241205T200557
[2024-12-05T20:05:57.660+0000] {standard_task_runner.py:110} ERROR - Failed to execute job 486 for task dbt_run (Bash command failed. The command returned a non-zero exit code 2.; 1778)
[2024-12-05T20:05:57.693+0000] {local_task_job_runner.py:240} INFO - Task exited with return code 1
[2024-12-05T20:05:57.707+0000] {taskinstance.py:3498} INFO - 0 downstream tasks scheduled from follow-on schedule check
[2024-12-05T20:05:57.709+0000] {local_task_job_runner.py:222} INFO - ::endgroup::
